Workbook

Sheet Нэгтгэл
A2: 2025 оны жилийн зардал
A5: Сар | B5: НӨАТ | C5: Цэвэр дүн | D5: Нийт дүн | E5: Татварын төрөл | F5: Цэвэр дүн | G5: Оффис хангамж | H5: Зээл | I5: Хүнс / кэмп | J5: ХАБ | K5: Хангамж | L5: Засварт | M5: Сэлбэг | N5: Түлш | O5: Тос тосолгоо | P5: Цалин | Q5: НӨӨЦ ашигласны төлбөр | R5: торгууль | S5: Лиценз | T5: Нийгмийн Хариуцлага | U5: Нөхөн сэргэлтийн төлбөр | V5: хогны төлбөр | W5: газрын төлбөр | X5: Суутган | Y5: НДШ | Z5: нийт зардал | AA5: Зардлын зөрүү
A6: 1 сар | B6: =+'1'!D4 -> 0 | C6: =+'1'!E4 -> 12063669 | D6: =+'1'!F4 -> 12063669 | E6: =+'1'!G4 -> 0 | F6: =+'1'!H4 -> 12063669 | G6: =+'1'!I4 -> 4000 | H6: =+'1'!J4 -> 12059669 | I6: =+'1'!K4 -> 0 | ... AA6: =+'1'!AC4 -> 0
A7: 2 сар | B7: =+'2'!D4 -> 9281.82 | C7: =+'2'!E4 -> 12091232 | D7: =+'2'!F4 -> 12081950 | E7: =+'2'!G4 -> 0 | F7: =+'2'!H4 -> 12081950 | G7: =+'2'!I4 -> 96818.18 | H7: =+'2'!J4 -> 11985132 | I7: =+'2'!K4 -> 0 | ... AA7: =+'2'!AC4 -> 0
A8: 3 сар | B8: =+'3'!D4 -> 12909.086 | C8: =+'3'!E4 -> 10750323 | D8: =+'3'!F4 -> 10737413 | E8: =+'3'!G4 -> 0 | F8: =+'3'!H4 -> 10737413 | G8: =+'3'!I4 -> 132090.91 | H8: =+'3'!J4 -> 10605323 | I8: =+'3'!K4 -> 0 | ... AA8: =+'3'!AC4 -> 0
A9: 4 сар | B9: =+'4'!D4 -> 13181.82 | C9: =+'4'!E4 -> 9599257.4 | D9: =+'4'!F4 -> 9586075.6 | E9: =+'4'!G4 -> 0 | F9: =+'4'!H4 -> 9586075.6 | G9: =+'4'!I4 -> 136818.18 | H9: =+'4'!J4 -> 9449257.4 | I9: =+'4'!K4 -> 0 | ... AB9: =+'4'!AD4 -> 0
A10: 5 сар | B10: =+'5'!D4 -> 1410487.5 | C10: =+'5'!E4 -> 29303280 | D10: =+'5'!F4 -> 27892793 | E10: =+'5'!G4 -> 0 | F10: =+'5'!H4 -> 27892793 | G10: =+'5'!I4 -> 4190350.6 | H10: =+'5'!J4 -> 12985423 | I10: =+'5'!K4 -> 1070672.6 | ... AA10: =+'5'!AC4 -> 0
A11: 6 сар | B11: =+'6'!D4 -> 547910.71 | C11: =+'6'!E4 -> 18916332 | D11: =+'6'!F4 -> 18368421 | E11: =+'6'!G4 -> 0 | F11: =+'6'!H4 -> 18368421 | G11: =+'6'!I4 -> 1384888.3 | H11: =+'6'!J4 -> 11037836 | I11: =+'6'!K4 -> 1309382.4 | ... AA11: =+'6'!AC4 -> 0
A12: Хагас жил | B12: =SUM(B6:B11) -> 1993770.9 | C12: =SUM(C6:C11) -> 92724092 | D12: =SUM(D6:D11) -> 90730321 | E12: =SUM(E6:E11) -> 0 | F12: =SUM(F6:F11) -> 90730321 | G12: =SUM(G6:G11) -> 5944966.1 | H12: =SUM(H6:H11) -> 68122639 | I12: =SUM(I6:I11) -> 2380055 | ... AA12: =SUM(AA6:AA11) -> 0
A13: 7 сар | B13: =+'7'!D4 -> 2110895.7 | C13: =+'7'!E4 -> 40191422 | D13: =+'7'!F4 -> 38080556 | E13: =+'7'!G4 -> 0 | F13: =+'7'!H4 -> 72430129 | G13: =+'7'!I4 -> 10629018 | H13: =+'7'!J4 -> 20042925 | I13: =+'7'!K4 -> 3561661 | ... AA13: =+'7'!AC4 -> 0
A14: 8 сар | B14: =+'8'!D4 -> 1907763.8 | C14: =+'8'!E4 -> 34214521 | D14: =+'8'!F4 -> 32306757 | E14: =+'8'!G4 -> 0 | F14: =+'8'!H4 -> 1.2372557e+08 | G14: =+'8'!I4 -> 14399963 | H14: =+'8'!J4 -> 25340203 | I14: =+'8'!K4 -> 4229736 | ... AA14: =+'8'!AC4 -> 0
A15: 9 сар | B15: =+'9'!D4 -> 252525.9 | C15: =+'9'!E4 -> 6302615.2 | D15: =+'9'!F4 -> 6050089.3 | E15: =+'9'!G4 -> 0 | F15: =+'9'!H4 -> 6302615.2 | G15: =+'9'!I4 -> 2774173 | H15: =+'9'!J4 -> 1762775.2 | I15: =+'9'!K4 -> 149600 | ... AA15: =+'9'!AC4 -> 0
A16: 10 сар
A17: 11 сар
A18: 12 сар
A19: Хагас жил | B19: =SUM(B13:B18) -> 4271185.4 | C19: =SUM(C13:C18) -> 80708558 | D19: =SUM(D13:D18) -> 76437402 | E19: =SUM(E13:E18) -> 0 | F19: =SUM(F13:F18) -> 2.0245832e+08 | G19: =SUM(G13:G18) -> 27803154 | H19: =SUM(H13:H18) -> 47145904 | I19: =SUM(I13:I18) -> 7940997 | ... AA19: =SUM(AA13:AA18) -> 0

Sheet 1
A3: Сар | B3: Харилцагчийн нэр | C3: Харилцагчийн ТТД | D3: НӨАТ | E3: Цэвэр дүн | F3: Нийт дүн | G3: Татварын төрөл | H3: Цэвэр дүн | I3: Оффис хангамж | J3: Зээл | K3: Хүнс / кэмп | L3: ХАБ | M3: Хангамж | N3: Засварт | O3: Сэлбэг | P3: Түлш | Q3: Тос тосолгоо | R3: Цалин | S3: НӨӨЦ ашигласны төлбөр | T3: торгууль | U3: Лиценз | V3: Нийгмийн Хариуцлага | W3: Нөхөн сэргэлтийн төлбөр | X3: хогны төлбөр | Y3: газрын төлбөр | Z3: Суутган | AA3: НДШ | AB3: нийт зардал | AC3: Зардлын зөрүү
D4: =SUM(D6:D162) -> 0 | E4: =SUM(E6:E162) -> 12063669 | F4: =SUM(F6:F162) -> 12063669 | H4: =+AB4 -> 12063669 | I4: =SUM(I6:I162) -> 4000 | J4: =SUM(J6:J162) -> 12059669 | K4: =SUM(K6:K162) -> 0 | L4: =SUM(L6:L162) -> 0 | M4: =SUM(M6:M162) -> 0 | N4: =SUM(N6:N162) -> 0 | O4: =SUM(O6:O162) -> 0 | P4: =SUM(P6:P162) -> 0 | ... AA4: =SUM(AA6:AA162) -> 0 | AB4: =SUM(I4:AA4) -> 12063669 | AC4: =SUM(AC6:AC162) -> 0
F5: 1 | I5: =+I4/$H$4 -> 0.00033157409 | K5: =+K4/$H$4 -> 0 | L5: =+L4/$H$4 -> 0 | M5: =+M4/$H$4 -> 0 | N5: =+N4/$H$4 -> 0 | O5: =+O4/$H$4 -> 0 | P5: =+P4/$H$4 -> 0 | Q5: =+Q4/$H$4 -> 0 | R5: =+R4/$H$4 -> 0 | ... AC5: =+AC4/$H$4 -> 0
A6: 2025-01-31 | B6: Инвескор ББСБ | C6: 6060854 | D6: 0 | E6: 9784108.7 | F6: =+E6-D6 -> 9784108.7 | G6: Чөлөөлөгдөх | H6: =+F6 -> 9784108.7 | J6: =+F6 -> 9784108.7 | AB6: =SUM(I6:AA6) -> 9784108.7 | AC6: =+AB6-H6 -> 0
A7: 2025-01-31 | B7: ХААН банк | C7: 2693321 | D7: 0 | E7: 2000 | F7: =+E7-D7 -> 2000 | G7: Чөлөөлөгдөх | H7: =+F7 -> 2000 | I7: =+F7 -> 2000 | AB7: =SUM(I7:AA7) -> 2000 | AC7: =+AB7-H7 -> 0
A8: 2025-01-15 | B8: Очир ундраа ОМЗ ББСБ | C8: 2734745 | D8: 0 | E8: 2275560 | F8: =+E8-D8 -> 2275560 | G8: Чөлөөлөгдөх | H8: =+F8 -> 2275560 | J8: =+F8 -> 2275560 | AB8: =SUM(I8:AA8) -> 2275560 | AC8: =+AB8-H8 -> 0
A9: 2025-01-01 | B9: Капитронбанк | C9: 2677377 | D9: 0 | E9: 2000 | F9: =+E9-D9 -> 2000 | G9: Чөлөөлөгдөх | H9: =+F9 -> 2000 | I9: =+F9 -> 2000 | AB9: =SUM(I9:AA9) -> 2000 | AC9: =+AB9-H9 -> 0
H10: =+F10 -> 0 | AC10: =+AB10-H10 -> 0
AC11: =+AB11-H11 -> 0

Sheet 2
A3: Сар | B3: Харилцагчийн нэр | C3: Харилцагчийн ТТД | D3: НӨАТ | E3: Цэвэр дүн | F3: Нийт дүн | G3: Татварын төрөл | H3: Нийт Зардал | I3: Оффис хангамж | J3: Зээл | K3: Хүнс / кэмп | L3: ХАБ | M3: Хангамж | N3: Засварт | O3: Сэлбэг | P3: Түлш | Q3: Тос тосолгоо | R3: Цалин | S3: НӨӨЦ ашигласны төлбөр | T3: торгууль | U3: Лиценз | V3: Нийгмийн Хариуцлага | W3: Нөхөн сэргэлтийн төлбөр | X3: хогны төлбөр | Y3: газрын төлбөр | Z3: Суутган | AA3: НДШ | AB3: нийт зардал | AC3: Зардлын зөрүү
D4: =SUM(D6:D162) -> 9281.82 | E4: =SUM(E6:E162) -> 12091232 | F4: =SUM(F6:F162) -> 12081950 | H4: =+AB4 -> 12081950 | I4: =SUM(I6:I162) -> 96818.18 | J4: =SUM(J6:J162) -> 11985132 | K4: =SUM(K6:K162) -> 0 | L4: =SUM(L6:L162) -> 0 | M4: =SUM(M6:M162) -> 0 | N4: =SUM(N6:N162) -> 0 | O4: =SUM(O6:O162) -> 0 | P4: =SUM(P6:P162) -> 0 | ... AA4: =SUM(AA6:AA162) -> 0 | AB4: =SUM(I4:AA4) -> 12081950 | AC4: =SUM(AC6:AC162) -> 0
F5: 1 | I5: =+I4/$H$4 -> 0.0080134563 | K5: =+K4/$H$4 -> 0 | L5: =+L4/$H$4 -> 0 | M5: =+M4/$H$4 -> 0 | N5: =+N4/$H$4 -> 0 | O5: =+O4/$H$4 -> 0 | P5: =+P4/$H$4 -> 0 | Q5: =+Q4/$H$4 -> 0 | R5: =+R4/$H$4 -> 0 | ... AC5: =+AC4/$H$4 -> 0
A6: 2025-02-28 | B6: Худалдаа хөгжлийн банк | C6: 2635534 | D6: 0 | E6: 1000 | F6: =+E6-D6 -> 1000 | G6: Чөлөөлөгдөх | H6: =+F6 -> 1000 | I6: =+H6 -> 1000 | AB6: =SUM(I6:AA6) -> 1000 | AC6: =+H6-AB6 -> 0
A7: 2025-02-28 | B7: ХААН банк | C7: 2693321 | D7: 0 | E7: 2000 | F7: =+E7-D7 -> 2000 | G7: Чөлөөлөгдөх | H7: =+F7 -> 2000 | I7: =+H7 -> 2000 | AB7: =SUM(I7:AA7) -> 2000 | AC7: =+H7-AB7 -> 0
A8: 2025-02-26 | B8: Хөрс-Авто сервис | C8: 2090694 | D8: 9281.82 | E8: 102100 | F8: =+E8-D8 -> 92818.18 | G8: Энгийн | H8: =+F8 -> 92818.18 | I8: =+H8 -> 92818.18 | AB8: =SUM(I8:AA8) -> 92818.18 | AC8: =+H8-AB8 -> 0
A9: 2025-02-18 | B9: Очир ундраа ОМЗ ББСБ | C9: 2734745 | D9: 0 | E9: 2201022.4 | F9: =+E9-D9 -> 2201022.4 | G9: Чөлөөлөгдөх | H9: =+F9 -> 2201022.4 | J9: =+H9 -> 2201022.4 | AB9: =SUM(I9:AA9) -> 2201022.4 | AC9: =+H9-AB9 -> 0
A10: 2025-02-01 | B10: Худалдаа хөгжлийн банк | C10: 2635534 | D10: 0 | E10: 1000 | F10: =+E10-D10 -> 1000 | G10: Чөлөөлөгдөх | H10: =+F10 -> 1000 | I10: =+H10 -> 1000 | AB10: =SUM(I10:AA10) -> 1000 | AC10: =+H10-AB10 -> 0
A11: 2025-02-28 | B11: Инвескор ББСБ | C11: 6060854 | D11: 0 | E11: 9784109.6 | F11: =+E11-D11 -> 9784109.6 | H11: =+F11 -> 9784109.6 | J11: =+F11 -> 9784109.6 | AB11: =SUM(I11:AA11) -> 9784109.6 | AC11: =+H11-AB11 -> 0
AB12: =SUM(I12:AA12) -> 0 | AC12: =+H12-AB12 -> 0
AC13: =+H13-AB13 -> 0
AC14: =+H14-AB14 -> 0

Sheet 3
A3: Сар | B3: Харилцагчийн нэр | C3: Харилцагчийн ТТД | D3: НӨАТ | E3: Цэвэр дүн | F3: Нийт дүн | G3: Татварын төрөл | H3: Нийт Зардал | I3: Оффис хангамж | J3: Зээл | K3: Хүнс / кэмп | L3: ХАБ | M3: Хангамж | N3: Засварт | O3: Сэлбэг | P3: Түлш | Q3: Тос тосолгоо | R3: Цалин | S3: НӨӨЦ ашигласны төлбөр | T3: торгууль | U3: Лиценз | V3: Нийгмийн Хариуцлага | W3: Нөхөн сэргэлтийн төлбөр | X3: хогны төлбөр | Y3: газрын төлбөр | Z3: Суутган | AA3: НДШ | AB3: нийт зардал | AC3: Зардлын зөрүү
D4: =SUM(D6:D162) -> 12909.086 | E4: =SUM(E6:E162) -> 10750323 | F4: =SUM(F6:F162) -> 10737413 | H4: =+AB4 -> 10737413 | I4: =SUM(I6:I162) -> 132090.91 | J4: =SUM(J6:J162) -> 10605323 | K4: =SUM(K6:K162) -> 0 | L4: =SUM(L6:L162) -> 0 | M4: =SUM(M6:M162) -> 0 | N4: =SUM(N6:N162) -> 0 | O4: =SUM(O6:O162) -> 0 | P4: =SUM(P6:P162) -> 0 | ... AA4: =SUM(AA6:AA162) -> 0 | AB4: =SUM(I4:AA4) -> 10737413 | AC4: =SUM(AC6:AC162) -> 0
F5: 1 | I5: =+I4/$H$4 -> 0.01230193 | K5: =+K4/$H$4 -> 0 | L5: =+L4/$H$4 -> 0 | M5: =+M4/$H$4 -> 0 | N5: =+N4/$H$4 -> 0 | O5: =+O4/$H$4 -> 0 | P5: =+P4/$H$4 -> 0 | Q5: =+Q4/$H$4 -> 0 | R5: =+R4/$H$4 -> 0 | ... AC5: =+AC4/$H$4 -> 0
A6: 2025-03-31 | B6: Инвескор ББСБ | C6: 6060854 | D6: 0 | E6: 8683468.9 | F6: =+E6-D6 -> 8683468.9 | G6: Энгийн | H6: =+F6 -> 8683468.9 | J6: =+H6 -> 8683468.9 | AB6: =SUM(I6:AA6) -> 8683468.9 | AC6: =+AB6-H6 -> 0
A7: 2025-03-31 | B7: Худалдаа хөгжлийн банк | C7: 2635534 | D7: 0 | E7: 1000 | F7: =+E7-D7 -> 1000 | G7: Энгийн | H7: =+F7 -> 1000 | I7: =+H7 -> 1000 | AB7: =SUM(I7:AA7) -> 1000 | AC7: =SUM(AC9:AC165) -> 0
A8: 2025-03-31 | B8: Финикс экүйпмент | C8: 5959918 | D8: 8363.6364 | E8: 92000 | F8: =+E8-D8 -> 83636.364 | H8: =+F8 -> 83636.364 | I8: =+H8 -> 83636.364 | AB8: =SUM(I8:AA8) -> 83636.364 | AC8: =SUM(AC10:AC166) -> 0
A9: 2025-03-31 | B9: ХААН банк | C9: 2693321 | D9: 0 | E9: 2000 | F9: =+E9-D9 -> 2000 | H9: =+F9 -> 2000 | I9: =+H9 -> 2000 | AB9: =SUM(I9:AA9) -> 2000 | AC9: =SUM(AC11:AC167) -> 0
A10: 2025-03-30 | B10: Шунхлайтрейдинг | C10: 5506239 | D10: 4545.45 | E10: 50000 | F10: =+E10-D10 -> 45454.55 | H10: =+F10 -> 45454.55 | I10: =+H10 -> 45454.55 | AB10: =SUM(I10:AA10) -> 45454.55
A11: 2025-03-10 | B11: Очир ундраа ОМЗ ББСБ | C11: 2734745 | D11: 0 | E11: 1921853.6 | F11: =+E11-D11 -> 1921853.6 | H11: =+F11 -> 1921853.6 | J11: =+H11 -> 1921853.6

Sheet 4
D2: 13,181.82₮ | E2: 9,599,257.41₮ | F2: 9,586,075.59₮
A3: Сар | B3: Харилцагчийн нэр | C3: Харилцагчийн ТТД | D3: НӨАТ | E3: Цэвэр дүн | F3: Нийт дүн | G3: Татварын төрөл | H3: Нийт Зардал | I3: Оффис хангамж | J3: Зээл | K3: Хүнс / кэмп | L3: ХАБ | M3: Хангамж | N3: Засварт | O3: Сэлбэг | P3: Түлш | Q3: Тос тосолгоо | R3: Цалин | S3: НӨӨЦ ашигласны төлбөр | T3: торгууль | U3: Лиценз | V3: Нийгмийн Хариуцлага | W3: Нөхөн сэргэлтийн төлбөр | X3: хогны төлбөр | Y3: газрын төлбөр | Z3: Суутган | AA3: НДШ | AB3: нийт зардал | AC3: Зардлын зөрүү
D4: =SUM(D6:D162) -> 13181.82 | E4: =SUM(E6:E162) -> 9599257.4 | F4: =SUM(F6:F162) -> 9586075.6 | H4: =+AB4 -> 9586075.6 | I4: =SUM(I6:I162) -> 136818.18 | J4: =SUM(J6:J162) -> 9449257.4 | K4: =SUM(K6:K162) -> 0 | L4: =SUM(L6:L162) -> 0 | M4: =SUM(M6:M162) -> 0 | N4: =SUM(N6:N162) -> 0 | O4: =SUM(O6:O162) -> 0 | P4: =SUM(P6:P162) -> 0 | ... AA4: =SUM(AA6:AA162) -> 0 | AB4: =SUM(I4:AA4) -> 9586075.6 | AC4: =SUM(AC6:AC162) -> 0
F5: 1 | I5: =+I4/$H$4 -> 0.014272596 | K5: =+K4/$H$4 -> 0 | L5: =+L4/$H$4 -> 0 | M5: =+M4/$H$4 -> 0 | N5: =+N4/$H$4 -> 0 | O5: =+O4/$H$4 -> 0 | P5: =+P4/$H$4 -> 0 | Q5: =+Q4/$H$4 -> 0 | R5: =+R4/$H$4 -> 0 | ... AC5: =+AC4/$H$4 -> 0
A6: 2025-04-30 | B6: Худалдаа хөгжлийн банк | C6: 2635534 | D6: 0 | E6: 1000 | F6: =+E6-D6 -> 1000 | G6: Энгийн | H6: =+F6 -> 1000 | I6: =+F6 -> 1000 | AB6: =SUM(I6:AA6) -> 1000 | AC6: =+AB6-H6 -> 0
A7: 2025-04-30 | B7: Инвескор ББСБ | C7: 6060854 | D7: 0 | E7: 9449257.4 | F7: =+E7-D7 -> 9449257.4 | G7: Энгийн | H7: =+F7 -> 9449257.4 | J7: =+H7 -> 9449257.4 | AB7: =SUM(I7:AA7) -> 9449257.4 | AC7: =+AB7-H7 -> 0
A8: 2025-04-30 | B8: ХААН банк | C8: 2693321 | D8: 0 | E8: 2000 | F8: =+E8-D8 -> 2000 | H8: =+F8 -> 2000 | I8: =+E8 -> 2000 | AB8: =SUM(I8:AA8) -> 2000 | AC8: =+AB8-H8 -> 0
A9: 2025-04-24 | B9: Тридум-Эсекьюрити | C9: 5126096 | D9: 4090.91 | E9: 45000 | F9: =+E9-D9 -> 40909.09 | H9: =+F9 -> 40909.09 | I9: =+H9 -> 40909.09 | AB9: =SUM(I9:AA9) -> 40909.09 | AC9: =+AB9-H9 -> 0
A10: 2025-04-23 | B10: Шунхлайтрейдинг | C10: 5506239 | D10: 9090.91 | E10: 100000 | F10: =+E10-D10 -> 90909.09 | H10: =+F10 -> 90909.09 | I10: =+F10 -> 90909.09 | AB10: =SUM(I10:AA10) -> 90909.09 | AC10: =+AB10-H10 -> 0
A11: 2025-04-01 | B11: Капитронбанк | C11: 2677377 | D11: 0 | E11: 2000 | F11: =+E11-D11 -> 2000 | H11: =+F11 -> 2000 | I11: =+F11 -> 2000 | AB11: =SUM(I11:AA11) -> 2000 | AC11: =+AB11-H11 -> 0
H12: =+F12 -> 0 | AB12: =SUM(I12:AA12) -> 0 | AC12: =+AB12-H12 -> 0
H13: =+F13 -> 0 | AC13: =+AB13-H13 -> 0
AC14: =+AB14-H14 -> 0
AC15: =+AB15-H15 -> 0
AC16: =+AB16-H16 -> 0

Sheet 5
G1: НХАТ | H1: 35107.03
D2: 1,410,487.47₮ | E2: 29,268,173.09₮ | F2: 27,857,685.62₮
A3: Сар | B3: Харилцагчийн нэр | C3: Харилцагчийн ТТД | D3: НӨАТ | E3: Цэвэр дүн | F3: Нийт дүн | G3: Татварын төрөл | H3: Нийт Зардал | I3: Оффис хангамж | J3: Зээл | K3: Хүнс / кэмп | L3: ХАБ | M3: Хангамж | N3: Засварт | O3: Сэлбэг | P3: Түлш | Q3: Тос тосолгоо | R3: Цалин | S3: НӨӨЦ ашигласны төлбөр | T3: торгууль | U3: Лиценз | V3: Нийгмийн Хариуцлага | W3: Нөхөн сэргэлтийн төлбөр | X3: хогны төлбөр | Y3: газрын төлбөр | Z3: Суутган | AA3: НДШ | AB3: нийт зардал | AC3: Зардлын зөрүү
D4: =SUM(D6:D162) -> 1410487.5 | E4: =SUM(E6:E162) -> 29303280 | F4: =SUM(F6:F162) -> 27892793 | H4: =+AB4 -> 27892793 | I4: =SUM(I6:I162) -> 4190350.6 | J4: =SUM(J6:J162) -> 12985423 | K4: =SUM(K6:K162) -> 1070672.6 | L4: =SUM(L6:L162) -> 0 | M4: =SUM(M6:M162) -> 330863.64 | N4: =SUM(N6:N162) -> 8363410.7 | O4: =SUM(O6:O162) -> 952072.07 | P4: =SUM(P6:P162) -> 0 | ... AA4: =SUM(AA6:AA162) -> 0 | AB4: =SUM(I4:AA4) -> 27892793 | AC4: =SUM(AC6:AC162) -> 0
F5: 1 | I5: =+I4/$H$4 -> 0.15023059 | K5: =+K4/$H$4 -> 0.038385276 | L5: =+L4/$H$4 -> 0 | M5: =+M4/$H$4 -> 0.011861976 | N5: =+N4/$H$4 -> 0.29984128 | O5: =+O4/$H$4 -> 0.034133265 | P5: =+P4/$H$4 -> 0 | Q5: =+Q4/$H$4 -> 0 | R5: =+R4/$H$4 -> 0 | ... AC5: =+AC4/$H$4 -> 0
A6: 2025-05-31 | B6: Худалдаа хөгжлийн банк | C6: 2635534 | D6: 0 | E6: 1000 | F6: =+E6-D6 -> 1000 | G6: Чөлөөлөгдөх | H6: =+F6 -> 1000 | I6: =+H6 -> 1000 | AB6: =SUM(I6:AA6) -> 1000 | AC6: =+AB6-F6 -> 0
A7: 2025-05-31 | B7: Эрхэмхангай | C7: 5430836 | D7: 3545.45 | E7: 39000 | F7: =+E7-D7 -> 35454.55 | G7: Энгийн | H7: =+F7 -> 35454.55 | K7: =+H7 -> 35454.55 | AB7: =SUM(I7:AA7) -> 35454.55 | AC7: =+AB7-F7 -> 0
A8: 2025-05-31 | B8: Зул маргад | C8: 6983243 | D8: 927.27273 | E8: 10200 | F8: =+E8-D8 -> 9272.7273 | G8: Энгийн | H8: =+F8 -> 9272.7273 | I8: =+H8 -> 9272.7273 | AB8: =SUM(I8:AA8) -> 9272.7273 | AC8: =+AB8-F8 -> 0
A9: 2025-05-31 | B9: ТОГТООЛ ЦЭВЭЛЛХАСҮРЭН | C9: НН75050868 | D9: 0 | E9: 63500 | F9: =+E9-D9 -> 63500 | G9: Энгийн | H9: =+F9 -> 63500 | J9: =+H9 -> 63500 | AB9: =SUM(I9:AA9) -> 63500 | AC9: =+AB9-F9 -> 0
A10: 2025-05-31 | B10: ХААН банк | C10: 2693321 | D10: 0 | E10: 2000 | F10: =+E10-D10 -> 2000 | G10: Чөлөөлөгдөх | H10: =+F10 -> 2000 | I10: =+H10 -> 2000 | AB10: =SUM(I10:AA10) -> 2000 | AC10: =+AB10-F10 -> 0
A11: 2025-05-30 | B11: Их ноён од | C11: 6007066 | D11: 118181.82 | E11: 1300000 | F11: =+E11-D11 -> 1181818.2 | G11: Энгийн | H11: =+F11 -> 1181818.2 | I11: =+H11 -> 1181818.2 | AB11: =SUM(I11:AA11) -> 1181818.2 | AC11: =+AB11-F11 -> 0
A12: 2025-05-30 | B12: Петростар | C12: 5241901 | D12: 15163.64 | E12: 166800 | F12: =+E12-D12 -> 151636.36 | G12: Энгийн | H12: =+F12 -> 151636.36 | I12: =+H12 -> 151636.36 | AB12: =SUM(I12:AA12) -> 151636.36 | AC12: =+AB12-F12 -> 0
A13: 2025-05-30 | B13: Ньюбулл | C13: 2679396 | D13: 37285.714 | E13: 417600 | F13: =+E13-D13 -> 380314.29 | G13: Энгийн | H13: =+F13 -> 380314.29 | I13: =+H13 -> 380314.29 | AB13: =SUM(I13:AA13) -> 380314.29 | AC13: =+AB13-F13 -> 0
A14: 2025-05-30 | B14: ТТЕМ | C14: 5459591 | D14: 77100 | E14: 848100 | F14: =+E14-D14 -> 771000 | G14: Энгийн | H14: =+F14 -> 771000 | O14: =+H14 -> 771000 | AB14: =SUM(I14:AA14) -> 771000 | AC14: =+AB14-F14 -> 0
A15: 2025-05-29 | B15: Содмонгол групп | C15: 2577739 | D15: 9090.91 | E15: 100000 | F15: =+E15-D15 -> 90909.09 | G15: Энгийн | H15: =+F15 -> 90909.09 | I15: =+H15 -> 90909.09 | AB15: =SUM(I15:AA15) -> 90909.09 | AC15: =+AB15-F15 -> 0
A16: 2025-05-28 | B16: Алханатрейд | C16: 2595192 | D16: 10000 | E16: 110000 | F16: =+E16-D16 -> 100000 | G16: Энгийн | H16: =+F16 -> 100000 | I16: =+H16 -> 100000 | AB16: =SUM(I16:AA16) -> 100000 | AC16: =+AB16-F16 -> 0
A17: 2025-05-28 | B17: Глобал инноватив фүүд трэжүр | C17: 6799272 | D17: 26080.36 | E17: 292100 | F17: =+E17-D17 -> 266019.64 | G17: Энгийн | H17: =+F17 -> 266019.64 | K17: =+H17 -> 266019.64 | AB17: =SUM(I17:AA17) -> 266019.64 | AC17: =+AB17-F17 -> 0
A18: 2025-05-28 | B18: ХУЛАНЗАЯА | C18: 2614057 | D18: 963.63636 | E18: 10600 | F18: =+E18-D18 -> 9636.3636 | G18: Энгийн | H18: =+F18 -> 9636.3636 | K18: =+H18 -> 9636.3636 | AB18: =SUM(I18:AA18) -> 9636.3636 | AC18: =+AB18-F18 -> 0
A19: 2025-05-28 | B19: Нарлаг толгод | C19: 8420963 | D19: 6800 | E19: 74800 | F19: =+E19-D19 -> 68000 | G19: Энгийн | H19: =+F19 -> 68000 | I19: =+H19 -> 68000 | AB19: =SUM(I19:AA19) -> 68000 | AC19: =+AB19-F19 -> 0
A20: 2025-05-27 | B20: Алтаннаран од | C20: 5177944 | D20: 28839.29 | E20: 323000 | F20: =+E20-D20 -> 294160.71 | G20: Энгийн | H20: =+F20 -> 294160.71 | N20: =+H20 -> 294160.71 | AB20: =SUM(I20:AA20) -> 294160.71 | AC20: =+AB20-F20 -> 0
A21: 2025-05-27 | B21: Нарлаг толгод | C21: 8420963 | D21: 3372.73 | E21: 37100 | F21: =+E21-D21 -> 33727.27 | G21: Энгийн | H21: =+F21 -> 33727.27 | I21: =+H21 -> 33727.27 | AB21: =SUM(I21:AA21) -> 33727.27 | AC21: =+AB21-F21 -> 0
A22: 2025-05-27 | B22: Нарлаг толгод | C22: 8420963 | D22: 15454.55 | E22: 170000 | F22: =+E22-D22 -> 154545.45 | G22: Энгийн | H22: =+F22 -> 154545.45 | I22: =+H22 -> 154545.45 | AB22: =SUM(I22:AA22) -> 154545.45 | AC22: =+AB22-F22 -> 0
A23: 2025-05-27 | B23: Нарлаг толгод | C23: 8420963 | D23: 15454.55 | E23: 170000 | F23: =+E23-D23 -> 154545.45 | G23: Энгийн | H23: =+F23 -> 154545.45 | I23: =+H23 -> 154545.45 | AB23: =SUM(I23:AA23) -> 154545.45 | AC23: =+AB23-F23 -> 0
A24: 2025-05-27 | B24: Нарлаг толгод | C24: 8420963 | D24: 4727.27 | E24: 52000 | F24: =+E24-D24 -> 47272.73 | G24: Энгийн | H24: =+F24 -> 47272.73 | I24: =+H24 -> 47272.73 | AB24: =SUM(I24:AA24) -> 47272.73 | AC24: =+AB24-F24 -> 0
A25: 2025-05-26 | B25: Гэрлэн сондор | C25: 5970849 | D25: 6818.1818 | E25: 75000 | F25: =+E25-D25 -> 68181.818 | G25: Энгийн | H25: =+F25 -> 68181.818 | K25: =+H25 -> 68181.818 | AB25: =SUM(I25:AA25) -> 68181.818 | AC25: =+AB25-F25 -> 0
A26: 2025-05-26 | B26: Сибкабель энержи | C26: 5391571 | D26: 181818.18 | E26: 2000000 | F26: =+E26-D26 -> 1818181.8 | G26: Энгийн | H26: =+F26 -> 1818181.8 | N26: =+H26 -> 1818181.8 | AB26: =SUM(I26:AA26) -> 1818181.8 | AC26: =+AB26-F26 -> 0
A27: 2025-05-26 | B27: Инвескор ББСБ | C27: 6060854 | D27: 0 | E27: 24813.55 | F27: =+E27-D27 -> 24813.55 | G27: Чөлөөлөгдөх | H27: =+F27 -> 24813.55 | J27: =+H27 -> 24813.55 | AB27: =SUM(I27:AA27) -> 24813.55 | AC27: =+AB27-F27 -> 0
A28: 2025-05-26 | B28: Инвескор ББСБ | C28: 6060854 | D28: 0 | E28: 8944895.8 | F28: =+E28-D28 -> 8944895.8 | G28: Чөлөөлөгдөх | H28: =+F28 -> 8944895.8 | J28: =+H28 -> 8944895.8 | AB28: =SUM(I28:AA28) -> 8944895.8 | AC28: =+AB28-F28 -> 0
A29: 2025-05-24 | B29: Буурал чилсаана | C29: 7013617 | D29: 0 | E29: 30020 | F29: =+E29-D29 -> 30020 | G29: Чөлөөлөгдөх | H29: =+F29 -> 30020 | I29: =+H29 -> 30020 | AB29: =SUM(I29:AA29) -> 30020 | AC29: =+AB29-F29 -> 0
A30: 2025-05-24 | B30: Буурал чилсаана | C30: 7013617 | D30: 15081.006 | E30: 168150 | F30: =+E30-D30 -> 153068.99 | G30: Энгийн | H30: =+F30 -> 153068.99 | I30: =+H30 -> 153068.99 | AB30: =SUM(I30:AA30) -> 153068.99 | AC30: =+AB30-F30 -> 0
A31: 2025-05-24 | B31: Шунхлайтрейдинг | C31: 5506239 | D31: 15120.91 | E31: 166330 | F31: =+E31-D31 -> 151209.09 | G31: Энгийн | H31: =+F31 -> 151209.09 | I31: =+H31 -> 151209.09 | AB31: =SUM(I31:AA31) -> 151209.09 | AC31: =+AB31-F31 -> 0
A32: 2025-05-24 | B32: Синчи газ | C32: 2638126 | D32: 0 | E32: 49500 | F32: =+E32-D32 -> 49500 | G32: Чөлөөлөгдөх | H32: =+F32 -> 49500 | M32: =+H32 -> 49500 | AB32: =SUM(I32:AA32) -> 49500 | AC32: =+AB32-F32 -> 0
A33: 2025-05-23 | B33: АЛТАНЖОЛОО ТРЕЙД | C33: 2057441 | D33: 22434.55 | E33: 246780 | F33: =+E33-D33 -> 224345.45 | G33: Энгийн | H33: =+F33 -> 224345.45 | I33: =+H33 -> 224345.45 | AB33: =SUM(I33:AA33) -> 224345.45 | AC33: =+AB33-F33 -> 0
A34: 2025-05-23 | B34: Нарлаг толгод | C34: 8420963 | D34: 1662.91 | E34: 18292 | F34: =+E34-D34 -> 16629.09 | G34: Энгийн | H34: =+F34 -> 16629.09 | I34: =+H34 -> 16629.09 | AB34: =SUM(I34:AA34) -> 16629.09 | AC34: =+AB34-F34 -> 0
A35: 2025-05-22 | B35: Нарлаг толгод | C35: 8420963 | D35: 1727.27 | E35: 19000 | F35: =+E35-D35 -> 17272.73 | G35: Энгийн | H35: =+F35 -> 17272.73 | I35: =+H35 -> 17272.73 | AB35: =SUM(I35:AA35) -> 17272.73 | AC35: =+AB35-F35 -> 0
A36: 2025-05-22 | B36: Эзэн цахар | C36: 6081193 | D36: 17927.93 | E36: 199000 | F36: =+E36-D36 -> 181072.07 | G36: Энгийн | H36: =+F36 -> 181072.07 | O36: =+H36 -> 181072.07 | AB36: =SUM(I36:AA36) -> 181072.07 | AC36: =+AB36-F36 -> 0
A37: 2025-05-21 | B37: Содмонгол групп | C37: 2577739 | D37: 4545.45 | E37: 50000 | F37: =+E37-D37 -> 45454.55 | G37: Энгийн | H37: =+F37 -> 45454.55 | I37: =+H37 -> 45454.55 | AB37: =SUM(I37:AA37) -> 45454.55 | AC37: =+AB37-F37 -> 0
A38: 2025-05-21 | B38: Нарлаг толгод | C38: 8420963 | D38: 3409.09 | E38: 37500 | F38: =+E38-D38 -> 34090.91 | G38: Энгийн | H38: =+F38 -> 34090.91 | I38: =+H38 -> 34090.91 | AB38: =SUM(I38:AA38) -> 34090.91 | AC38: =+AB38-F38 -> 0
A39: 2025-05-21 | B39: Юнигаз | C39: 2847817 | D39: 0 | E39: 117136 | F39: =+E39-D39 -> 117136 | G39: Чөлөөлөгдөх | H39: =+F39 -> 117136 | I39: =+H39 -> 117136 | AB39: =SUM(I39:AA39) -> 117136 | AC39: =+AB39-F39 -> 0
A40: 2025-05-20 | B40: Мобиком корпораци | C40: 2072572 | D40: 26272.73 | E40: 289000 | F40: =+E40-D40 -> 262727.27 | G40: Энгийн | H40: =+F40 -> 262727.27 | I40: =+H40 -> 262727.27 | AB40: =SUM(I40:AA40) -> 262727.27 | AC40: =+AB40-F40 -> 0
...

Sheet 6
G1: 11,097.86₮
D2: 547,910.71₮ | E2: 18,905,233.76₮ | F2: 18,357,323.05₮
A3: Сар | B3: Харилцагчийн нэр | C3: Харилцагчийн ТТД | D3: НӨАТ | E3: Цэвэр дүн | F3: Нийт дүн | G3: Татварын төрөл | H3: Нийт Зардал | I3: Оффис хангамж | J3: Зээл | K3: Хүнс / кэмп | L3: ХАБ | M3: Хангамж | N3: Засварт | O3: Сэлбэг | P3: Түлш | Q3: Тос тосолгоо | R3: Цалин | S3: НӨӨЦ ашигласны төлбөр | T3: торгууль | U3: Лиценз | V3: Нийгмийн Хариуцлага | W3: Нөхөн сэргэлтийн төлбөр | X3: хогны төлбөр | Y3: газрын төлбөр | Z3: Суутган | AA3: НДШ | AB3: нийт зардал | AC3: Зардлын зөрүү
D4: =SUM(D6:D162) -> 547910.71 | E4: =SUM(E6:E162) -> 18916332 | F4: =SUM(F6:F162) -> 18368421 | H4: =+AB4 -> 18368421 | I4: =SUM(I6:I162) -> 1384888.3 | J4: =SUM(J6:J162) -> 11037836 | K4: =SUM(K6:K162) -> 1309382.4 | L4: =SUM(L6:L162) -> 0 | M4: =SUM(M6:M162) -> 414309.09 | N4: =SUM(N6:N162) -> 220000 | O4: =SUM(O6:O162) -> 0 | P4: =SUM(P6:P162) -> 1353641.8 | ... AA4: =SUM(AA6:AA162) -> 0 | AB4: =SUM(I4:AA4) -> 18368421 | AC4: =SUM(AC6:AC162) -> 0
F5: 1 | I5: =+I4/$H$4 -> 0.075395065 | K5: =+K4/$H$4 -> 0.07128443 | L5: =+L4/$H$4 -> 0 | M5: =+M4/$H$4 -> 0.022555509 | N5: =+N4/$H$4 -> 0.011977077 | O5: =+O4/$H$4 -> 0 | P5: =+P4/$H$4 -> 0.073693969 | Q5: =+Q4/$H$4 -> 0.14418026 | R5: =+R4/$H$4 -> 0 | ... AC5: =+AC4/$H$4 -> 0
A6: 2025-06-30 | B6: Худалдаа хөгжлийн банк | C6: 2635534 | D6: 0 | E6: 1000 | F6: =+E6-D6 -> 1000 | G6: Чөлөөлөгдөх | H6: =+F6 -> 1000 | I6: =+H6 -> 1000 | AB6: =SUM(I6:AA6) -> 1000 | AC6: =+AB6-H6 -> 0 | AD6: Нөат
A7: 2025-06-30 | B7: Петростар | C7: 5241901 | D7: 4545.45 | E7: 50000 | F7: =+E7-D7 -> 45454.55 | G7: Энгийн | H7: =+F7 -> 45454.55 | P7: =+H7 -> 45454.55 | AB7: =SUM(I7:AA7) -> 45454.55 | AC7: =+AB7-H7 -> 0 | AD7: Нөат
A8: 2025-06-30 | B8: ХААН банк | C8: 2693321 | D8: 0 | E8: 2000 | F8: =+E8-D8 -> 2000 | G8: Чөлөөлөгдөх | H8: =+F8 -> 2000 | I8: =+H8 -> 2000 | AB8: =SUM(I8:AA8) -> 2000 | AC8: =+AB8-H8 -> 0 | AD8: Нөат
A9: 2025-06-29 | B9: Сүү | C9: 2077108 | D9: 0 | E9: 4900 | F9: =+E9-D9 -> 4900 | G9: Чөлөөлөгдөх | H9: =+F9 -> 4900 | K9: =+H9 -> 4900 | AB9: =SUM(I9:AA9) -> 4900 | AC9: =+AB9-H9 -> 0 | AD9: Нөат
A10: 2025-06-29 | B10: Сүү | C10: 2077108 | D10: 1327.27 | E10: 14600 | F10: =+E10-D10 -> 13272.73 | G10: Энгийн | H10: =+F10 -> 13272.73 | K10: =+H10 -> 13272.73 | AB10: =SUM(I10:AA10) -> 13272.73 | AC10: =+AB10-H10 -> 0 | AD10: Нөат
A11: 2025-06-29 | B11: Максхүнс | C11: 5046688 | D11: 11372.73 | E11: 125100 | F11: =+E11-D11 -> 113727.27 | G11: Энгийн | H11: =+F11 -> 113727.27 | K11: =+H11 -> 113727.27 | AB11: =SUM(I11:AA11) -> 113727.27 | AC11: =+AB11-H11 -> 0 | AD11: Нөат
A12: 2025-06-29 | B12: Шунхлайтрейдинг | C12: 5506239 | D12: 2727.27 | E12: 30000 | F12: =+E12-D12 -> 27272.73 | G12: Энгийн | H12: =+F12 -> 27272.73 | P12: =+H12 -> 27272.73 | AB12: =SUM(I12:AA12) -> 27272.73 | AC12: =+AB12-H12 -> 0 | AD12: Нөат
A13: 2025-06-29 | B13: Синчи газ | C13: 2638126 | D13: 0 | E13: 49500 | F13: =+E13-D13 -> 49500 | G13: Чөлөөлөгдөх | H13: =+F13 -> 49500 | M13: =+H13 -> 49500 | AB13: =SUM(I13:AA13) -> 49500 | AC13: =+AB13-H13 -> 0 | AD13: Нөат
A14: 2025-06-27 | B14: Эрхэмхангай | C14: 5430836 | D14: 7200 | E14: 79200 | F14: =+E14-D14 -> 72000 | G14: Энгийн | H14: =+F14 -> 72000 | K14: =+H14 -> 72000 | AB14: =SUM(I14:AA14) -> 72000 | AC14: =+AB14-H14 -> 0 | AD14: Нөат
A15: 2025-06-26 | B15: Дашваанжил групп | C15: 2025191 | D15: 0 | E15: 60000 | F15: =+E15-D15 -> 60000 | G15: Чөлөөлөгдөх | H15: =+F15 -> 60000 | M15: =+H15 -> 60000 | AB15: =SUM(I15:AA15) -> 60000 | AC15: =+AB15-H15 -> 0 | AD15: Нөат
A16: 2025-06-26 | B16: Содмонгол групп | C16: 2577739 | D16: 13636.36 | E16: 150000 | F16: =+E16-D16 -> 136363.64 | G16: Энгийн | H16: =+F16 -> 136363.64 | P16: =+H16 -> 136363.64 | AB16: =SUM(I16:AA16) -> 136363.64 | AC16: =+AB16-H16 -> 0 | AD16: Нөат
A17: 2025-06-25 | B17: Алханатрейд | C17: 2595192 | D17: 4545.45 | E17: 50000 | F17: =+E17-D17 -> 45454.55 | G17: Энгийн | H17: =+F17 -> 45454.55 | P17: =+H17 -> 45454.55 | AB17: =SUM(I17:AA17) -> 45454.55 | AC17: =+AB17-H17 -> 0 | AD17: Нөат
A18: 2025-06-25 | B18: Очир ундраа ОМЗ ББСБ | C18: 2734745 | D18: 0 | E18: 226.54 | F18: =+E18-D18 -> 226.54 | G18: Чөлөөлөгдөх | H18: =+F18 -> 226.54 | J18: =+H18 -> 226.54 | AB18: =SUM(I18:AA18) -> 226.54 | AC18: =+AB18-H18 -> 0 | AD18: Нөат
A19: 2025-06-25 | B19: Инвескор ББСБ | C19: 6060854 | D19: 0 | E19: 48908.49 | F19: =+E19-D19 -> 48908.49 | G19: Чөлөөлөгдөх | H19: =+F19 -> 48908.49 | J19: =+H19 -> 48908.49 | AB19: =SUM(I19:AA19) -> 48908.49 | AC19: =+AB19-H19 -> 0 | AD19: Нөат
A20: 2025-06-25 | B20: Инвескор ББСБ | C20: 6060854 | D20: 0 | E20: 9055567.1 | F20: =+E20-D20 -> 9055567.1 | G20: Чөлөөлөгдөх | H20: =+F20 -> 9055567.1 | J20: =+H20 -> 9055567.1 | AB20: =SUM(I20:AA20) -> 9055567.1 | AC20: =+AB20-H20 -> 0 | AD20: Нөат
A21: 2025-06-25 | B21: Аж-Эрдэнэ | C21: 2876256 | D21: 9000 | E21: 99000 | F21: =+E21-D21 -> 90000 | G21: Энгийн | H21: =+F21 -> 90000 | N21: =+H21 -> 90000 | AB21: =SUM(I21:AA21) -> 90000 | AC21: =+AB21-H21 -> 0 | AD21: Нөат
A22: 2025-06-25 | B22: Аж-Эрдэнэ | C22: 2876256 | D22: 13000 | E22: 143000 | F22: =+E22-D22 -> 130000 | G22: Энгийн | H22: =+F22 -> 130000 | N22: =+H22 -> 130000 | AB22: =SUM(I22:AA22) -> 130000 | AC22: =+AB22-H22 -> 0 | AD22: Нөат
A23: 2025-06-25 | B23: Солюшн ойл | C23: 6584055 | D23: 82700 | E23: 909700 | F23: =+E23-D23 -> 827000 | G23: Энгийн | H23: =+F23 -> 827000 | Q23: =+H23 -> 827000 | AB23: =SUM(I23:AA23) -> 827000 | AC23: =+AB23-H23 -> 0 | AD23: Нөат
A24: 2025-06-24 | B24: МТ петролиум | C24: 5043913 | D24: 4545.4545 | E24: 50000 | F24: =+E24-D24 -> 45454.545 | G24: Энгийн | H24: =+F24 -> 45454.545 | P24: =+H24 -> 45454.545 | AB24: =SUM(I24:AA24) -> 45454.545 | AC24: =+AB24-H24 -> 0 | AD24: Нөат
A25: 2025-06-24 | B25: Зул маргад | C25: 6983243 | D25: 3290.9091 | E25: 36200 | F25: =+E25-D25 -> 32909.091 | G25: Энгийн | H25: =+F25 -> 32909.091 | I25: =+H25 -> 32909.091 | AB25: =SUM(I25:AA25) -> 32909.091 | AC25: =+AB25-H25 -> 0 | AD25: Нөат
A26: 2025-06-24 | B26: Монос-Улаанбаатар | C26: 2708558 | D26: 1820.91 | E26: 20030 | F26: =+E26-D26 -> 18209.09 | G26: Энгийн | H26: =+F26 -> 18209.09 | I26: =+H26 -> 18209.09 | AB26: =SUM(I26:AA26) -> 18209.09 | AC26: =+AB26-H26 -> 0 | AD26: Нөат
A27: 2025-06-24 | B27: Нарлаг толгод | C27: 8420963 | D27: 18356.17 | E27: 203900 | F27: =+E27-D27 -> 185543.83 | G27: Энгийн | H27: =+F27 -> 185543.83 | I27: =+H27 -> 185543.83 | AB27: =SUM(I27:AA27) -> 185543.83 | AC27: =+AB27-H27 -> 0 | AD27: Нөат
A28: 2025-06-23 | B28: Хаянхярваа ОЮУНТУЯА | C28: УЮ87072401 | D28: 182136.36 | E28: 2003500 | F28: =+E28-D28 -> 1821363.6 | G28: Энгийн | H28: =+F28 -> 1821363.6 | Q28: =+H28 -> 1821363.6 | AB28: =SUM(I28:AA28) -> 1821363.6 | AC28: =+AB28-H28 -> 0 | AD28: Нөат
A29: 2025-06-22 | B29: Алханатрейд | C29: 2595192 | D29: 3636.36 | E29: 40000 | F29: =+E29-D29 -> 36363.64 | G29: Энгийн | H29: =+F29 -> 36363.64 | P29: =+H29 -> 36363.64 | AB29: =SUM(I29:AA29) -> 36363.64 | AC29: =+AB29-H29 -> 0 | AD29: Нөат
A30: 2025-06-22 | B30: Синчи газ | C30: 2638126 | D30: 0 | E30: 49500 | F30: =+E30-D30 -> 49500 | G30: Чөлөөлөгдөх | H30: =+F30 -> 49500 | M30: =+H30 -> 49500 | AB30: =SUM(I30:AA30) -> 49500 | AC30: =+AB30-H30 -> 0 | AD30: Нөат
A31: 2025-06-22 | B31: Мобиком корпораци | C31: 2072572 | D31: 2263.64 | E31: 24900 | F31: =+E31-D31 -> 22636.36 | G31: Энгийн | H31: =+F31 -> 22636.36 | I31: =+H31 -> 22636.36 | AB31: =SUM(I31:AA31) -> 22636.36 | AC31: =+AB31-H31 -> 0 | AD31: Нөат
A32: 2025-06-21 | B32: Шунхлайтрейдинг | C32: 5506239 | D32: 4545.45 | E32: 50000 | F32: =+E32-D32 -> 45454.55 | G32: Энгийн | H32: =+F32 -> 45454.55 | P32: =+H32 -> 45454.55 | AB32: =SUM(I32:AA32) -> 45454.55 | AC32: =+AB32-H32 -> 0 | AD32: Нөат
A33: 2025-06-20 | B33: Ньюбулл | C33: 2679396 | D33: 20401.786 | E33: 228500 | F33: =+E33-D33 -> 208098.21 | G33: Энгийн | H33: =+F33 -> 208098.21 | I33: =+H33 -> 208098.21 | AB33: =SUM(I33:AA33) -> 208098.21 | AC33: =+AB33-H33 -> 0 | AD33: Нөат
A34: 2025-06-20 | B34: Баян өндөр констракшн | C34: 6260063 | D34: 14090.91 | E34: 155000 | F34: =+E34-D34 -> 140909.09 | G34: Энгийн | H34: =+F34 -> 140909.09 | I34: =+H34 -> 140909.09 | AB34: =SUM(I34:AA34) -> 140909.09 | AC34: =+AB34-H34 -> 0 | AD34: Нөат
A35: 2025-06-20 | B35: Мобиком корпораци | C35: 2072572 | D35: 2909.09 | E35: 32000 | F35: =+E35-D35 -> 29090.91 | G35: Энгийн | H35: =+F35 -> 29090.91 | I35: =+H35 -> 29090.91 | AB35: =SUM(I35:AA35) -> 29090.91 | AC35: =+AB35-H35 -> 0 | AD35: Нөат
A36: 2025-06-20 | B36: Нарлаг толгод | C36: 8420963 | D36: 3145.45 | E36: 34600 | F36: =+E36-D36 -> 31454.55 | G36: Энгийн | H36: =+F36 -> 31454.55 | I36: =+H36 -> 31454.55 | AB36: =SUM(I36:AA36) -> 31454.55 | AC36: =+AB36-H36 -> 0 | AD36: Нөат
A37: 2025-06-17 | B37: Хулст толгой | C37: 6025587 | D37: 4331.82 | E37: 47650 | F37: =+E37-D37 -> 43318.18 | G37: Энгийн | H37: =+F37 -> 43318.18 | K37: =+H37 -> 43318.18 | AB37: =SUM(I37:AA37) -> 43318.18 | AC37: =+AB37-H37 -> 0 | AD37: Нөат
A38: 2025-06-16 | B38: Синчи газ | C38: 2638126 | D38: 0 | E38: 49500 | F38: =+E38-D38 -> 49500 | G38: Чөлөөлөгдөх | H38: =+F38 -> 49500 | M38: =+H38 -> 49500 | AB38: =SUM(I38:AA38) -> 49500 | AC38: =+AB38-H38 -> 0 | AD38: Нөат
A39: 2025-06-15 | B39: Найманталт уул | C39: 5057884 | D39: 9000 | E39: 99000 | F39: =+E39-D39 -> 90000 | G39: Энгийн | H39: =+F39 -> 90000 | K39: =+H39 -> 90000 | AB39: =SUM(I39:AA39) -> 90000 | AC39: =+AB39-H39 -> 0 | AD39: Нөат
A40: 2025-06-15 | B40: Монмийт трейд | C40: 5136113 | D40: 0 | E40: 290360 | F40: =+E40-D40 -> 290360 | G40: Чөлөөлөгдөх | H40: =+F40 -> 290360 | K40: =+H40 -> 290360 | AB40: =SUM(I40:AA40) -> 290360 | AC40: =+AB40-H40 -> 0 | AD40: Нөат
...

Sheet 7
G1: 28,992.65₮ | I1: НӨАТ | J1: 40161420 | K1: =+J2+J1 -> 72402856
D2: 2,110,895.69₮ | E2: 40,162,427.78₮ | F2: 38,051,532.09₮ | J2: 32241436
A3: Сар | B3: Харилцагчийн нэр | C3: Харилцагчийн ТТД | D3: НӨАТ | E3: Цэвэр дүн | F3: Нийт дүн | G3: Татварын төрөл | H3: Нийт Зардал | I3: Оффис хангамж | J3: Зээл | K3: Хүнс / кэмп | L3: ХАБ | M3: Хангамж | N3: Засварт | O3: Сэлбэг | P3: Түлш | Q3: Тос тосолгоо | R3: Цалин | S3: НӨӨЦ ашигласны төлбөр | T3: торгууль | U3: Лиценз | V3: Нийгмийн Хариуцлага | W3: Нөхөн сэргэлтийн төлбөр | X3: хогны төлбөр | Y3: газрын төлбөр | Z3: Суутган | AA3: НДШ | AB3: нийт зардал | AC3: Зардлын зөрүү | AD3: нөат
D4: =SUM(D6:D145) -> 2110895.7 | E4: =SUM(E6:E145) -> 40191422 | F4: =SUM(F6:F145) -> 38080556 | H4: =SUM(H6:H436) -> 72430129 | I4: =SUM(I6:I436) -> 10629018 | J4: =SUM(J6:J436) -> 20042925 | K4: =SUM(K6:K436) -> 3561661 | L4: =SUM(L6:L436) -> 392000 | M4: =SUM(M6:M436) -> 6844350 | N4: =SUM(N6:N436) -> 10373800 | O4: =SUM(O6:O436) -> 11354900 | ... AA4: =SUM(AA6:AA436) -> 0 | AB4: =SUM(I4:AA4) -> 72430129 | AC4: =SUM(AC6:AC145) -> 0
F5: 1 | I5: =+I4/$H$4 -> 0.14674857 | K5: =+K4/$H$4 -> 0.049173749 | L5: =+L4/$H$4 -> 0.0054121124 | M5: =+M4/$H$4 -> 0.094495897 | N5: =+N4/$H$4 -> 0.14322493 | O5: =+O4/$H$4 -> 0.1567704 | P5: =+P4/$H$4 -> 0.076162707 | Q5: =+Q4/$H$4 -> 0.043006965 | R5: =+R4/$H$4 -> 0 | ... AC5: =+AC4/$H$4 -> 0
A6: 2025-07-01 | B6: Капитронбанк | C6: 2677377 | D6: 0 | E6: 2000 | F6: 2000 | G6: Чөлөөлөгдөх | H6: =+E6 -> 2000 | I6: 2000 | AB6: =SUM(I6:AA6) -> 2000 | AC6: =+AB6-H6 -> 0 | AD6: нөат
A7: 2025-07-01 | B7: Синчи-Ойл | C7: 2588617 | D7: 2727.27 | E7: 30000 | F7: 27272.73 | G7: Энгийн | H7: =+E7 -> 30000 | P7: =+H7 -> 30000 | AB7: =SUM(I7:AA7) -> 30000 | AC7: =+AB7-H7 -> 0 | AD7: нөат
A8: 2025-07-01 | B8: Синчи-Ойл | C8: 2588617 | D8: 2727.27 | E8: 30000 | F8: 27272.73 | G8: Энгийн | H8: =+E8 -> 30000 | P8: =+H8 -> 30000 | AB8: =SUM(I8:AA8) -> 30000 | AC8: =+AB8-H8 -> 0 | AD8: нөат
A9: 2025-07-01 | B9: Алтан их бүс | C9: 5922321 | D9: 2727.27 | E9: 30000 | F9: 27272.73 | G9: Энгийн | H9: =+E9 -> 30000 | O9: =+H9 -> 30000 | AB9: =SUM(I9:AA9) -> 30000 | AC9: =+AB9-H9 -> 0 | AD9: нөат
A10: 2025-07-01 | B10: Шунхлайтрейдинг | C10: 5506239 | D10: 7386.73 | E10: 81254 | F10: 73867.27 | G10: Энгийн | H10: =+E10 -> 81254 | P10: =+H10 -> 81254 | AB10: =SUM(I10:AA10) -> 81254 | AC10: =+AB10-H10 -> 0 | AD10: нөат
A11: 2025-07-01 | B11: Дэ булл хот пот | C11: 7045057 | D11: 35062.5 | E11: 392700 | F11: 357637.5 | G11: Энгийн | H11: =+E11 -> 392700 | I11: =+H11 -> 392700 | AB11: =SUM(I11:AA11) -> 392700 | AC11: =+AB11-H11 -> 0 | AD11: нөат
A12: 2025-07-02 | B12: Синчи-Ойл | C12: 2588617 | D12: 4545.45 | E12: 50000 | F12: 45454.55 | G12: Энгийн | H12: =+E12 -> 50000 | P12: =+H12 -> 50000 | AB12: =SUM(I12:AA12) -> 50000 | AC12: =+AB12-H12 -> 0 | AD12: нөат
A13: 2025-07-02 | B13: Ганхуяг БОЛОР-ЭРДЭНЭ | C13: УЦ91010711 | D13: 24490.91 | E13: 269400 | F13: 244909.09 | G13: Энгийн | H13: =+E13 -> 269400 | M13: =+H13 -> 269400 | AB13: =SUM(I13:AA13) -> 269400 | AC13: =+AB13-H13 -> 0 | AD13: нөат
A14: 2025-07-03 | B14: Содмонгол групп | C14: 2577739 | D14: 2727.27 | E14: 30000 | F14: 27272.73 | G14: Энгийн | H14: =+E14-D14 -> 27272.73 | P14: =+H14 -> 27272.73 | AB14: =SUM(I14:AA14) -> 27272.73 | AC14: =+AB14-H14 -> 0
A15: 2025-07-03 | B15: ГОМБО ДЭЛГЭРМАА | C15: ШЕ70110962 | D15: 0 | E15: 47000 | F15: 47000 | G15: Энгийн | H15: =+E15 -> 47000 | M15: =+H15 -> 47000 | AB15: =SUM(I15:AA15) -> 47000 | AC15: =+AB15-H15 -> 0 | AD15: нөат
A16: 2025-07-03 | B16: Алханатрейд | C16: 2595192 | D16: 6363.64 | E16: 70000 | F16: 63636.36 | G16: Энгийн | H16: =+E16 -> 70000 | O16: =+H16 -> 70000 | AB16: =SUM(I16:AA16) -> 70000 | AC16: =+AB16-H16 -> 0 | AD16: нөат
A17: 2025-07-03 | B17: Өсөх идэр ирээдүй | C17: 6548644 | D17: 6500 | E17: 71500 | F17: 65000 | G17: Энгийн | H17: =+E17 -> 71500 | O17: =+H17 -> 71500 | AB17: =SUM(I17:AA17) -> 71500 | AC17: =+AB17-H17 -> 0 | AD17: нөат
A18: 2025-07-03 | B18: Нарлаг толгод | C18: 8420963 | D18: 7347.24 | E18: 80900 | F18: 73552.76 | G18: Энгийн | H18: =+E18 -> 80900 | K18: =+H18 -> 80900 | AB18: =SUM(I18:AA18) -> 80900 | AC18: =+AB18-H18 -> 0 | AD18: нөат
A19: 2025-07-03 | B19: Ньюбулл | C19: 2679396 | D19: 11232.143 | E19: 125800 | F19: 114567.86 | G19: Энгийн | H19: =+E19 -> 125800 | I19: =+H19 -> 125800 | AB19: =SUM(I19:AA19) -> 125800 | AC19: =+AB19-H19 -> 0 | AD19: нөат
A20: 2025-07-03 | B20: Дашваанжил групп | C20: 2025191 | D20: 0 | E20: 475000 | F20: 475000 | G20: Чөлөөлөгдөх | H20: =+E20 -> 475000 | P20: =+H20 -> 475000 | AB20: =SUM(I20:AA20) -> 475000 | AC20: =+AB20-H20 -> 0 | AD20: нөат
A21: 2025-07-04 | B21: Нарлаг толгод | C21: 8420963 | D21: 1263.64 | E21: 13900 | F21: 12636.36 | G21: Энгийн | H21: =+E21 -> 13900 | K21: =+H21 -> 13900 | AB21: =SUM(I21:AA21) -> 13900 | AC21: =+AB21-H21 -> 0 | AD21: нөат
A22: 2025-07-05 | B22: Ганболд ЦЭЛМЭГ | C22: УП04310154 | D22: 537.09 | E22: 5908 | F22: 5370.91 | G22: Энгийн | H22: =+E22 -> 5908 | I22: =+H22 -> 5908 | AB22: =SUM(I22:AA22) -> 5908 | AC22: =+AB22-H22 -> 0 | AD22: нөат
A23: 2025-07-05 | B23: ЧУЛУУНХҮҮ ДОЛЖИНСҮРЭН | C23: ЧС60090569 | D23: 0 | E23: 19500 | F23: 19500 | G23: Энгийн | H23: =+E23 -> 19500 | I23: =+H23 -> 19500 | AB23: =SUM(I23:AA23) -> 19500 | AC23: =+AB23-H23 -> 0 | AD23: нөат
A24: 2025-07-05 | B24: ГОМБО ДЭЛГЭРМАА | C24: ШЕ70110962 | D24: 0 | E24: 38000 | F24: 38000 | G24: Энгийн | H24: =+E24 -> 38000 | M24: =+H24 -> 38000 | AB24: =SUM(I24:AA24) -> 38000 | AC24: =+AB24-H24 -> 0 | AD24: нөат
A25: 2025-07-05 | B25: ЛХАМСҮРЭН ОТГОНБАЯР | C25: АЯ94060507 | D25: 3746.82 | E25: 41215 | F25: 37468.18 | G25: Энгийн | H25: =+E25 -> 41215 | I25: =+H25 -> 41215 | AB25: =SUM(I25:AA25) -> 41215 | AC25: =+AB25-H25 -> 0 | AD25: нөат
A26: 2025-07-05 | B26: Дашваанжил групп | C26: 2025191 | D26: 0 | E26: 57900 | F26: 57900 | G26: Чөлөөлөгдөх | H26: =+E26 -> 57900 | M26: =+H26 -> 57900 | AB26: =SUM(I26:AA26) -> 57900 | AC26: =+AB26-H26 -> 0 | AD26: нөат
A27: 2025-07-05 | B27: Хулхан | C27: 2744783 | D27: 7681.82 | E27: 84500 | F27: 76818.18 | G27: Энгийн | H27: =+E27 -> 84500 | K27: =+H27 -> 84500 | AB27: =SUM(I27:AA27) -> 84500 | AC27: =+AB27-H27 -> 0 | AD27: нөат
A28: 2025-07-05 | B28: Монсуль | C28: 2794241 | D28: 14295.45 | E28: 157250 | F28: 142954.55 | G28: Энгийн | H28: =+E28 -> 157250 | P28: =+H28 -> 157250 | AB28: =SUM(I28:AA28) -> 157250 | AC28: =+AB28-H28 -> 0 | AD28: нөат
A29: 2025-07-05 | B29: Петростар | C29: 5241901 | D29: 19792.91 | E29: 217722 | F29: 197929.09 | G29: Энгийн | H29: =+E29 -> 217722 | P29: =+H29 -> 217722 | AB29: =SUM(I29:AA29) -> 217722 | AC29: =+AB29-H29 -> 0 | AD29: нөат
A30: 2025-07-05 | B30: Номин бизнес клуб | C30: 6736106 | D30: 44094.64 | E30: 490439 | F30: 446344.36 | G30: Энгийн | H30: =+E30 -> 490439 | K30: =+H30 -> 490439 | AB30: =SUM(I30:AA30) -> 490439 | AC30: =+AB30-H30 -> 0 | AD30: нөат
A31: 2025-07-06 | B31: Ти Эм ойл | C31: 6099866 | D31: 13728.18 | E31: 151010 | F31: 137281.82 | G31: Энгийн | H31: =+E31 -> 151010 | P31: =+H31 -> 151010 | AB31: =SUM(I31:AA31) -> 151010 | AC31: =+AB31-H31 -> 0 | AD31: нөат
A32: 2025-07-07 | B32: ZEEL TULULT,ДЭМБЭРЭЛСҮРЭН ЭРДЭНЭЦЭЦЭГ,ХА | C32: ДЭМБЭРЭЛСҮРЭН ЭРДЭНЭЦЭЦЭГ | D32: MN230005005735021190 | F32: 1 | H32: 200000 | I32: 200000 | AB32: =SUM(I32:AA32) -> 200000 | AC32: =+AB32-H32 -> 0
A33: 2025-07-07 | B33: ZEEL TULULT,НУРМАА ЭРДЭНЭСҮХ,ХААН ТӨВ БА | C33: НУРМАА ЭРДЭНЭСҮХ | D33: MN170005005026304378 | F33: 1 | H33: 3160000 | J33: 3160000 | AB33: =SUM(I33:AA33) -> 3160000 | AC33: =+AB33-H33 -> 0
A34: 2025-07-07 | B34: АЛТАНГЭРЭЛ ЦАСЧИХЭР,СЭБҮ СТАДИ ТУР,ХААН ТӨВ БАНК | C34: СЭБҮ СТАДИ ТУР | E34: MN920005005431711327 | F34: 1 | H34: 6400000 | J34: 6400000 | AB34: =SUM(I34:AA34) -> 6400000 | AC34: =+AB34-H34 -> 0
A35: 2025-07-07 | B35: Улсын нэгдүгээр төв эмнэлэг | C35: 9077138 | D35: 0 | E35: 50000 | F35: 50000 | G35: Чөлөөлөгдөх | H35: =+E35 -> 50000 | L35: 50000 | AB35: =SUM(I35:AA35) -> 50000 | AC35: =+AB35-H35 -> 0 | AD35: нөат
A36: 2025-07-07 | B36: Синчи-Ойл | C36: 2588617 | D36: 4545.45 | E36: 50000 | F36: 45454.55 | G36: Энгийн | H36: =+E36 -> 50000 | P36: =+H36 -> 50000 | AB36: =SUM(I36:AA36) -> 50000 | AC36: =+AB36-H36 -> 0 | AD36: нөат
A37: 2025-07-07 | B37: Улсын нэгдүгээр төв эмнэлэг | C37: 9077138 | D37: 0 | E37: 320000 | F37: 320000 | G37: Чөлөөлөгдөх | H37: =+E37 -> 320000 | L37: 320000 | AB37: =SUM(I37:AA37) -> 320000 | AC37: =+AB37-H37 -> 0 | AD37: нөат
A38: 2025-07-08 | B38: INTERNET,ЭНХБАЯР БЯМБАХОРОЛ,ТӨРИЙН БАНК | C38: ЭНХБАЯР БЯМБАХОРОЛ | D38: MN050034360000378300 | F38: 1 | H38: 40000 | I38: =+H38 -> 40000 | AB38: =SUM(I38:AA38) -> 40000 | AC38: =+AB38-H38 -> 0
A39: 2025-07-08 | B39: 5899508 4 ХҮН,ХХҮЕГАЗАР,Төрийн сан | C39: ХХҮЕГАЗАР | D39: MN830090100900017002 | F39: 1 | H39: 120000 | I39: 120000 | AB39: =SUM(I39:AA39) -> 120000 | AC39: =+AB39-H39 -> 0
A40: 2025-07-08 | B40: Малтзсэлес | C40: 5205093 | D40: 636.36364 | E40: 7000 | F40: 6363.6364 | G40: Энгийн | H40: =+E40 -> 7000 | I40: =+H40 -> 7000 | AB40: =SUM(I40:AA40) -> 7000 | AC40: =+AB40-H40 -> 0 | AD40: нөат
...

Sheet 8
G1: 69,748.21₮ | I1: НӨАТ | J1: 86061461 | K1: =+J2+J1 -> 123725573
D2: 3,941,854.68₮ | E2: 85,991,712.59₮ | F2: 82,049,857.91₮ | J2: 37664112
A3: Сар | B3: Харилцагчийн нэр | C3: Харилцагчийн ТТД | D3: НӨАТ | E3: Цэвэр дүн | F3: Нийт дүн | G3: Татварын төрөл | H3: Нийт Зардал | I3: Оффис хангамж | J3: Зээл | K3: Хүнс / кэмп | L3: ХАБ | M3: Хангамж | N3: Засварт | O3: Сэлбэг | P3: Түлш | Q3: Тос тосолгоо | R3: Цалин | S3: НӨӨЦ ашигласны төлбөр | T3: торгууль | U3: Лиценз | V3: Нийгмийн Хариуцлага | W3: Нөхөн сэргэлтийн төлбөр | X3: хогны төлбөр | Y3: газрын төлбөр | Z3: Суутган | AA3: НДШ | AB3: нийт зардал | AC3: Зардлын зөрүү
D4: =SUM(D6:D162) -> 1907763.8 | E4: =SUM(E6:E162) -> 34214521 | F4: =SUM(F6:F162) -> 32306757 | H4: =SUM(H6:H262) -> 1.2372557e+08 | I4: =SUM(I6:I262) -> 14399963 | J4: =SUM(J6:J262) -> 25340203 | K4: =SUM(K6:K262) -> 4229736 | L4: =SUM(L6:L262) -> 5545860 | M4: =SUM(M6:M262) -> 6641990 | N4: =SUM(N6:N262) -> 15328635 | O4: =SUM(O6:O262) -> 20978250 | ... AA4: =SUM(AA6:AA262) -> 0 | AB4: =SUM(I4:AA4) -> 1.2372557e+08 | AC4: =SUM(AC6:AC162) -> 0
F5: 1 | I5: =+I4/$H$4 -> 0.11638631 | K5: =+K4/$H$4 -> 0.034186433 | L5: =+L4/$H$4 -> 0.044823878 | M5: =+M4/$H$4 -> 0.053683243 | N5: =+N4/$H$4 -> 0.12389221 | O5: =+O4/$H$4 -> 0.16955468 | P5: =+P4/$H$4 -> 0.23508426 | Q5: =+Q4/$H$4 -> 0.017579228 | R5: =+R4/$H$4 -> 0 | ... AC5: =+AC4/$H$4 -> 0
A6: 2025-08-01 | C6: Гүйлгээний шимтгэл | H6: 100 | I6: =+H6 -> 100 | AB6: =SUM(I6:AA6) -> 100 | AC6: =+AB6-H6 -> 0
A7: 2025-08-01 | B7: АЛТАНГЭРЭЛ БУДЖАВ | C7: Charges for PORD Customer Payment :000449092553 | H7: 200 | I7: =+H7 -> 200 | AB7: =SUM(I7:AA7) -> 200 | AC7: =+AB7-H7 -> 0
A8: 2025-08-01 | B8: АЛТАНГЭРЭЛ БУДЖАВ | C8: Charges for PORD Customer Payment :000449093268 | H8: 200 | I8: =+H8 -> 200 | AB8: =SUM(I8:AA8) -> 200 | AC8: =+AB8-H8 -> 0
A9: 2025-08-01 | B9: НУРМАА ЭРДЭНЭСҮХ | C9: Charges for PORD Customer Payment :000449364984 | H9: 200 | I9: =+H9 -> 200 | AB9: =SUM(I9:AA9) -> 200 | AC9: =+AB9-H9 -> 0
A10: 2025-08-01 | B10: АЛТАНГЭРЭЛ БУДЖАВ | C10: PP TULSH 20 L ZURUU,АЛТАНГЭРЭЛ БУДЖАВ,ХА | H10: 30000 | P10: 30000 | AB10: =SUM(I10:AA10) -> 30000 | AC10: =+AB10-H10 -> 0
A11: 2025-08-01 | B11: Синчи-Ойл | C11: 2588617 | D11: 4545.45 | E11: 50000 | F11: =+E11-D11 -> 45454.55 | G11: Энгийн | H11: =+E11 -> 50000 | I11: =+H11 -> 50000 | AB11: =SUM(I11:AA11) -> 50000 | AC11: =+AB11-H11 -> 0 | AD11: нөат
A12: 2025-08-01 | B12: Синчи-Ойл | C12: 2588617 | D12: 5090.91 | E12: 56000 | F12: =+E12-D12 -> 50909.09 | G12: Энгийн | H12: =+E12 -> 56000 | I12: =+H12 -> 56000 | AB12: =SUM(I12:AA12) -> 56000 | AC12: =+AB12-H12 -> 0 | AD12: нөат
A13: 2025-08-01 | B13: Алханатрейд | C13: 2595192 | D13: 18000 | E13: 198000 | F13: =+E13-D13 -> 180000 | G13: Энгийн | H13: =+E13 -> 198000 | O13: =+H13 -> 198000 | AB13: =SUM(I13:AA13) -> 198000 | AC13: =+AB13-H13 -> 0 | AD13: нөат
A14: 2025-08-01 | B14: Баялагжимс | C14: 5204569 | D14: 31972.909 | E14: 351702 | F14: =+E14-D14 -> 319729.09 | G14: Энгийн | H14: =+E14 -> 351702 | K14: =+H14 -> 351702 | AB14: =SUM(I14:AA14) -> 351702 | AC14: =+AB14-H14 -> 0 | AD14: нөат
A15: 2025-08-01 | B15: Очир ундраа ОМЗ ББСБ | C15: 2734745 | D15: 0 | E15: 1744508 | F15: =+E15-D15 -> 1744508 | G15: Чөлөөлөгдөх | H15: =+E15 -> 1744508 | J15: =+H15 -> 1744508 | AB15: =SUM(I15:AA15) -> 1744508 | AC15: =+AB15-H15 -> 0 | AD15: нөат
A16: 2025-08-01 | B16: ОЧИР УНДРАА ОМЗ ББСБ | C16: Б.ЭНХБАЯР, 88102299 | H16: 4289850 | J16: =H16 -> 4289850 | AB16: =SUM(I16:AA16) -> 4289850 | AC16: =+AB16-H16 -> 0
A17: 2025-08-02 | B17: Синчи-Ойл | C17: 2588617 | D17: 9090.91 | E17: 100000 | F17: =+E17-D17 -> 90909.09 | G17: Энгийн | H17: =+E17 -> 100000 | I17: =+H17 -> 100000 | AB17: =SUM(I17:AA17) -> 100000 | AC17: =+AB17-H17 -> 0 | AD17: нөат
A18: 2025-08-03 | B18: Нарлаг толгод | C18: 8420963 | D18: 6818.18 | E18: 75000 | F18: =+E18-D18 -> 68181.82 | G18: Энгийн | H18: =+E18 -> 75000 | I18: =+H18 -> 75000 | AB18: =SUM(I18:AA18) -> 75000 | AC18: =+AB18-H18 -> 0 | AD18: нөат
A19: 2025-08-03 | B19: Касс таун групп | C19: 6358128 | D19: 238803.57 | E19: 2674600 | F19: =+E19-D19 -> 2435796.4 | G19: Энгийн | H19: =+E19 -> 2674600 | O19: =+H19 -> 2674600 | AB19: =SUM(I19:AA19) -> 2674600 | AC19: =+AB19-H19 -> 0 | AD19: нөат
A20: 2025-08-04 | B20: ЭНХБАТ ЭРХЭС | C20: Charges for PORD Customer Payment :000450129391 | H20: 200 | I20: =+H20 -> 200 | AB20: =SUM(I20:AA20) -> 200 | AC20: =+AB20-H20 -> 0
A21: 2025-08-04 | B21: ОДБААТАР ОДГЭРЭЛ | C21: Charges for PORD Customer Payment :000450263017 | H21: 200 | I21: =+H21 -> 200 | AB21: =SUM(I21:AA21) -> 200 | AC21: =+AB21-H21 -> 0
A22: 2025-08-04 | B22: ПИРАМИДПРОГРЕСС | C22: Charges for PORD Customer Payment :000450283266 | H22: 200 | I22: =+H22 -> 200 | AB22: =SUM(I22:AA22) -> 200 | AC22: =+AB22-H22 -> 0
A23: 2025-08-04 | B23: ПИРАМИДПРОГРЕСС | C23: Charges for PORD Customer Payment :000450283415 | H23: 200 | I23: =+H23 -> 200 | AB23: =SUM(I23:AA23) -> 200 | AC23: =+AB23-H23 -> 0
A24: 2025-08-04 | B24: ПИРАМИДПРОГРЕСС | C24: Charges for PORD Customer Payment :000450283719 | H24: 200 | I24: =+H24 -> 200 | AB24: =SUM(I24:AA24) -> 200 | AC24: =+AB24-H24 -> 0
A25: 2025-08-04 | B25: ПИРАМИДПРОГРЕСС | C25: Charges for PORD Customer Payment :000450314756 | H25: 200 | I25: =+H25 -> 200 | AB25: =SUM(I25:AA25) -> 200 | AC25: =+AB25-H25 -> 0
A26: 2025-08-04 | B26: ПИРАМИДПРОГРЕСС | C26: Charges for PORD Customer Payment :000450315422 | H26: 200 | I26: =+H26 -> 200 | AB26: =SUM(I26:AA26) -> 200 | AC26: =+AB26-H26 -> 0
A27: 2025-08-04 | B27: Хос судар | C27: 6039731 | D27: 318.18182 | E27: 3500 | F27: =+E27-D27 -> 3181.8182 | G27: Энгийн | H27: =+E27 -> 3500 | K27: =+H27 -> 3500 | AB27: =SUM(I27:AA27) -> 3500 | AC27: =+AB27-H27 -> 0 | AD27: нөат
A28: 2025-08-04 | B28: ОДБААТАР ОДГЭРЭЛ | C28: TSAGIIN BURTGEL,ОДБААТАР ОДГЭРЭЛ,ХААН ТӨ | H28: 3500 | I28: 3500 | AB28: =SUM(I28:AA28) -> 3500 | AC28: =+AB28-H28 -> 0
A29: 2025-08-04 | B29: Ойнбирж | C29: 2026945 | D29: 9090.91 | E29: 100000 | F29: =+E29-D29 -> 90909.09 | G29: Энгийн | H29: =+E29 -> 100000 | I29: =+H29 -> 100000 | AB29: =SUM(I29:AA29) -> 100000 | AC29: =+AB29-H29 -> 0 | AD29: нөат
A30: 2025-08-04 | B30: Содон сондор гэрэлтүүлэг | C30: 3576388 | D30: 0 | E30: 121500 | F30: =+E30-D30 -> 121500 | G30: Энгийн | H30: =+E30 -> 121500 | O30: =+H30 -> 121500 | AB30: =SUM(I30:AA30) -> 121500 | AC30: =+AB30-H30 -> 0 | AD30: нөат
A31: 2025-08-04 | B31: ЭНХБАТ ЭРХЭС | C31: TSAGILGAAN ZASVAR 3 TEHBIK,ЭНХБАТ ЭРХЭС, | H31: 500000 | N31: 500000 | AB31: =SUM(I31:AA31) -> 500000 | AC31: =+AB31-H31 -> 0
A32: 2025-08-05 | B32: ДОРЖСҮРЭН БАЯРБАТ | C32: Charges for PORD Customer Payment :000450656537 | H32: 200 | I32: =+H32 -> 200 | AB32: =SUM(I32:AA32) -> 200 | AC32: =+AB32-H32 -> 0
A33: 2025-08-05 | B33: НЭРГҮЙ ХУЯГБААТАР | C33: Charges for PORD Customer Payment :000450671766 | H33: 200 | I33: =+H33 -> 200 | AB33: =SUM(I33:AA33) -> 200 | AC33: =+AB33-H33 -> 0
A34: 2025-08-05 | B34: БААСАНХҮҮ ЦОГГЭРЭЛ | C34: Charges for PORD Customer Payment :000450703037 | H34: 200 | I34: =+H34 -> 200 | AB34: =SUM(I34:AA34) -> 200 | AC34: =+AB34-H34 -> 0
A35: 2025-08-05 | B35: ОЧИР УНДРАА ОМЗ ББСБ | C35: Charges for PORD Customer Payment :000450712336 | H35: 200 | I35: =+H35 -> 200 | AB35: =SUM(I35:AA35) -> 200 | AC35: =+AB35-H35 -> 0
A36: 2025-08-05 | B36: БУЛЛ КАПИТАЛ ББСБ | C36: Charges for PORD Customer Payment :000450713638 | H36: 200 | I36: =+H36 -> 200 | AB36: =SUM(I36:AA36) -> 200 | AC36: =+AB36-H36 -> 0
A37: 2025-08-05 | B37: ЭРДЭНЭЧИМЭГ СОДГЭРЭЛ | C37: Charges for PORD Customer Payment :000450820509 | H37: 200 | I37: =+H37 -> 200 | AB37: =SUM(I37:AA37) -> 200 | AC37: =+AB37-H37 -> 0
A38: 2025-08-05 | B38: ХОЛООХ БАТНЯМ | C38: Charges for PORD Customer Payment :000450821953 | H38: 200 | I38: =+H38 -> 200 | AB38: =SUM(I38:AA38) -> 200 | AC38: =+AB38-H38 -> 0
A39: 2025-08-05 | B39: АРИУНБОЛД БАТСУУРЬ | C39: Charges for PORD Customer Payment :000450824044 | H39: 200 | I39: =+H39 -> 200 | AB39: =SUM(I39:AA39) -> 200 | AC39: =+AB39-H39 -> 0
A40: 2025-08-05 | B40: СҮРЭНЖАВ МӨНХЦЭЦЭГ | C40: Charges for PORD Customer Payment :000450824578 | H40: 200 | I40: =+H40 -> 200 | AB40: =SUM(I40:AA40) -> 200 | AC40: =+AB40-H40 -> 0
...

Sheet Sheet2
A1: Сар | B1: Харилцагчийн нэр | C1: Харилцагчийн ТТД | D1: НӨАТ | E1: Цэвэр дүн | F1: Нийт дүн | G1: Татварын төрөл | H1: Нийт Зардал | I1: Оффис хангамж | J1: Зээл | K1: Хүнс / кэмп | L1: ХАБ | M1: Хангамж | N1: Засварт | O1: Сэлбэг | P1: Түлш | Q1: Тос тосолгоо | R1: Цалин | S1: НӨӨЦ ашигласны төлбөр | T1: торгууль | U1: Лиценз | V1: Нийгмийн Хариуцлага | W1: Нөхөн сэргэлтийн төлбөр | X1: хогны төлбөр | Y1: газрын төлбөр | Z1: Суутган | AA1: НДШ | AB1: нийт зардал | AC1: Зардлын зөрүү
A2: 2025-08-01 | C2: Гүйлгээний шимтгэл | H2: 100 | I2: =+H2 -> 100 | AB2: =SUM(I2:AA2) -> 100 | AC2: =+AB2-H2 -> 0
A3: 2025-08-01 | B3: АЛТАНГЭРЭЛ БУДЖАВ | C3: Charges for PORD Customer Payment :000449092553 | H3: 200 | I3: =+H3 -> 200 | AB3: =SUM(I3:AA3) -> 200 | AC3: =+AB3-H3 -> 0
A4: 2025-08-01 | B4: АЛТАНГЭРЭЛ БУДЖАВ | C4: Charges for PORD Customer Payment :000449093268 | H4: 200 | I4: =+H4 -> 200 | AB4: =SUM(I4:AA4) -> 200 | AC4: =+AB4-H4 -> 0
A5: 2025-08-01 | B5: НУРМАА ЭРДЭНЭСҮХ | C5: Charges for PORD Customer Payment :000449364984 | H5: 200 | I5: =+H5 -> 200 | AB5: =SUM(I5:AA5) -> 200 | AC5: =+AB5-H5 -> 0
A6: 2025-08-01 | B6: АЛТАНГЭРЭЛ БУДЖАВ | C6: PP TULSH 20 L ZURUU,АЛТАНГЭРЭЛ БУДЖАВ,ХА | H6: 30000 | P6: 30000 | AB6: =SUM(I6:AA6) -> 30000 | AC6: =+AB6-H6 -> 0
A7: 2025-08-01 | B7: Синчи-Ойл | C7: 2588617 | D7: 4545.45 | E7: 50000 | F7: =+E7-D7 -> 45454.55 | G7: Энгийн | H7: =+E7 -> 50000 | I7: =+H7 -> 50000 | AB7: =SUM(I7:AA7) -> 50000 | AC7: =+AB7-H7 -> 0 | AD7: нөат
A8: 2025-08-01 | B8: Синчи-Ойл | C8: 2588617 | D8: 5090.91 | E8: 56000 | F8: =+E8-D8 -> 50909.09 | G8: Энгийн | H8: =+E8 -> 56000 | I8: =+H8 -> 56000 | AB8: =SUM(I8:AA8) -> 56000 | AC8: =+AB8-H8 -> 0 | AD8: нөат
A9: 2025-08-01 | B9: Алханатрейд | C9: 2595192 | D9: 18000 | E9: 198000 | F9: =+E9-D9 -> 180000 | G9: Энгийн | H9: =+E9 -> 198000 | O9: =+H9 -> 198000 | AB9: =SUM(I9:AA9) -> 198000 | AC9: =+AB9-H9 -> 0 | AD9: нөат
A10: 2025-08-01 | B10: Баялагжимс | C10: 5204569 | D10: 31972.909 | E10: 351702 | F10: =+E10-D10 -> 319729.09 | G10: Энгийн | H10: =+E10 -> 351702 | K10: =+H10 -> 351702 | AB10: =SUM(I10:AA10) -> 351702 | AC10: =+AB10-H10 -> 0 | AD10: нөат
A11: 2025-08-01 | B11: Очир ундраа ОМЗ ББСБ | C11: 2734745 | D11: 0 | E11: 1744508 | F11: =+E11-D11 -> 1744508 | G11: Чөлөөлөгдөх | H11: =+E11 -> 1744508 | J11: =+H11 -> 1744508 | AB11: =SUM(I11:AA11) -> 1744508 | AC11: =+AB11-H11 -> 0 | AD11: нөат
A12: 2025-08-01 | B12: ОЧИР УНДРАА ОМЗ ББСБ | C12: Б.ЭНХБАЯР, 88102299 | H12: 4289850 | J12: =H12 -> 4289850 | AB12: =SUM(I12:AA12) -> 4289850 | AC12: =+AB12-H12 -> 0
A13: 2025-08-02 | B13: Синчи-Ойл | C13: 2588617 | D13: 9090.91 | E13: 100000 | F13: =+E13-D13 -> 90909.09 | G13: Энгийн | H13: =+E13 -> 100000 | I13: =+H13 -> 100000 | AB13: =SUM(I13:AA13) -> 100000 | AC13: =+AB13-H13 -> 0 | AD13: нөат
A14: 2025-08-03 | B14: Нарлаг толгод | C14: 8420963 | D14: 6818.18 | E14: 75000 | F14: =+E14-D14 -> 68181.82 | G14: Энгийн | H14: =+E14 -> 75000 | I14: =+H14 -> 75000 | AB14: =SUM(I14:AA14) -> 75000 | AC14: =+AB14-H14 -> 0 | AD14: нөат
A15: 2025-08-03 | B15: Касс таун групп | C15: 6358128 | D15: 238803.57 | E15: 2674600 | F15: =+E15-D15 -> 2435796.4 | G15: Энгийн | H15: =+E15 -> 2674600 | O15: =+H15 -> 2674600 | AB15: =SUM(I15:AA15) -> 2674600 | AC15: =+AB15-H15 -> 0 | AD15: нөат
A16: 2025-08-04 | B16: ЭНХБАТ ЭРХЭС | C16: Charges for PORD Customer Payment :000450129391 | H16: 200 | I16: =+H16 -> 200 | AB16: =SUM(I16:AA16) -> 200 | AC16: =+AB16-H16 -> 0
A17: 2025-08-04 | B17: ОДБААТАР ОДГЭРЭЛ | C17: Charges for PORD Customer Payment :000450263017 | H17: 200 | I17: =+H17 -> 200 | AB17: =SUM(I17:AA17) -> 200 | AC17: =+AB17-H17 -> 0
A18: 2025-08-04 | B18: ПИРАМИДПРОГРЕСС | C18: Charges for PORD Customer Payment :000450283266 | H18: 200 | I18: =+H18 -> 200 | AB18: =SUM(I18:AA18) -> 200 | AC18: =+AB18-H18 -> 0
A19: 2025-08-04 | B19: ПИРАМИДПРОГРЕСС | C19: Charges for PORD Customer Payment :000450283415 | H19: 200 | I19: =+H19 -> 200 | AB19: =SUM(I19:AA19) -> 200 | AC19: =+AB19-H19 -> 0
A20: 2025-08-04 | B20: ПИРАМИДПРОГРЕСС | C20: Charges for PORD Customer Payment :000450283719 | H20: 200 | I20: =+H20 -> 200 | AB20: =SUM(I20:AA20) -> 200 | AC20: =+AB20-H20 -> 0
A21: 2025-08-04 | B21: ПИРАМИДПРОГРЕСС | C21: Charges for PORD Customer Payment :000450314756 | H21: 200 | I21: =+H21 -> 200 | AB21: =SUM(I21:AA21) -> 200 | AC21: =+AB21-H21 -> 0
A22: 2025-08-04 | B22: ПИРАМИДПРОГРЕСС | C22: Charges for PORD Customer Payment :000450315422 | H22: 200 | I22: =+H22 -> 200 | AB22: =SUM(I22:AA22) -> 200 | AC22: =+AB22-H22 -> 0
A23: 2025-08-04 | B23: Хос судар | C23: 6039731 | D23: 318.18182 | E23: 3500 | F23: =+E23-D23 -> 3181.8182 | G23: Энгийн | H23: =+E23 -> 3500 | K23: =+H23 -> 3500 | AB23: =SUM(I23:AA23) -> 3500 | AC23: =+AB23-H23 -> 0 | AD23: нөат
A24: 2025-08-04 | B24: ОДБААТАР ОДГЭРЭЛ | C24: TSAGIIN BURTGEL,ОДБААТАР ОДГЭРЭЛ,ХААН ТӨ | H24: 3500 | I24: 3500 | AB24: =SUM(I24:AA24) -> 3500 | AC24: =+AB24-H24 -> 0
A25: 2025-08-04 | B25: Ойнбирж | C25: 2026945 | D25: 9090.91 | E25: 100000 | F25: =+E25-D25 -> 90909.09 | G25: Энгийн | H25: =+E25 -> 100000 | I25: =+H25 -> 100000 | AB25: =SUM(I25:AA25) -> 100000 | AC25: =+AB25-H25 -> 0 | AD25: нөат
A26: 2025-08-04 | B26: Содон сондор гэрэлтүүлэг | C26: 3576388 | D26: 0 | E26: 121500 | F26: =+E26-D26 -> 121500 | G26: Энгийн | H26: =+E26 -> 121500 | O26: =+H26 -> 121500 | AB26: =SUM(I26:AA26) -> 121500 | AC26: =+AB26-H26 -> 0 | AD26: нөат
A27: 2025-08-04 | B27: ЭНХБАТ ЭРХЭС | C27: TSAGILGAAN ZASVAR 3 TEHBIK,ЭНХБАТ ЭРХЭС, | H27: 500000 | N27: 500000 | AB27: =SUM(I27:AA27) -> 500000 | AC27: =+AB27-H27 -> 0
A28: 2025-08-05 | B28: ДОРЖСҮРЭН БАЯРБАТ | C28: Charges for PORD Customer Payment :000450656537 | H28: 200 | I28: =+H28 -> 200 | AB28: =SUM(I28:AA28) -> 200 | AC28: =+AB28-H28 -> 0
A29: 2025-08-05 | B29: НЭРГҮЙ ХУЯГБААТАР | C29: Charges for PORD Customer Payment :000450671766 | H29: 200 | I29: =+H29 -> 200 | AB29: =SUM(I29:AA29) -> 200 | AC29: =+AB29-H29 -> 0
A30: 2025-08-05 | B30: БААСАНХҮҮ ЦОГГЭРЭЛ | C30: Charges for PORD Customer Payment :000450703037 | H30: 200 | I30: =+H30 -> 200 | AB30: =SUM(I30:AA30) -> 200 | AC30: =+AB30-H30 -> 0
A31: 2025-08-05 | B31: ОЧИР УНДРАА ОМЗ ББСБ | C31: Charges for PORD Customer Payment :000450712336 | H31: 200 | I31: =+H31 -> 200 | AB31: =SUM(I31:AA31) -> 200 | AC31: =+AB31-H31 -> 0
A32: 2025-08-05 | B32: БУЛЛ КАПИТАЛ ББСБ | C32: Charges for PORD Customer Payment :000450713638 | H32: 200 | I32: =+H32 -> 200 | AB32: =SUM(I32:AA32) -> 200 | AC32: =+AB32-H32 -> 0
A33: 2025-08-05 | B33: ЭРДЭНЭЧИМЭГ СОДГЭРЭЛ | C33: Charges for PORD Customer Payment :000450820509 | H33: 200 | I33: =+H33 -> 200 | AB33: =SUM(I33:AA33) -> 200 | AC33: =+AB33-H33 -> 0
A34: 2025-08-05 | B34: ХОЛООХ БАТНЯМ | C34: Charges for PORD Customer Payment :000450821953 | H34: 200 | I34: =+H34 -> 200 | AB34: =SUM(I34:AA34) -> 200 | AC34: =+AB34-H34 -> 0
A35: 2025-08-05 | B35: АРИУНБОЛД БАТСУУРЬ | C35: Charges for PORD Customer Payment :000450824044 | H35: 200 | I35: =+H35 -> 200 | AB35: =SUM(I35:AA35) -> 200 | AC35: =+AB35-H35 -> 0
A36: 2025-08-05 | B36: СҮРЭНЖАВ МӨНХЦЭЦЭГ | C36: Charges for PORD Customer Payment :000450824578 | H36: 200 | I36: =+H36 -> 200 | AB36: =SUM(I36:AA36) -> 200 | AC36: =+AB36-H36 -> 0
A37: 2025-08-05 | B37: БАТТОГТОХ ДОВЧИН | C37: Charges for PORD Customer Payment :000450825696 | H37: 200 | I37: =+H37 -> 200 | AB37: =SUM(I37:AA37) -> 200 | AC37: =+AB37-H37 -> 0
A38: 2025-08-05 | B38: ЛХААЖАВ ДАРИНЧУЛУУН | C38: Charges for PORD Customer Payment :000450826367 | H38: 200 | I38: =+H38 -> 200 | AB38: =SUM(I38:AA38) -> 200 | AC38: =+AB38-H38 -> 0
A39: 2025-08-05 | B39: ХУДАЙ ТӨМӨРХУЯГ | C39: Charges for PORD Customer Payment :000450828079 | H39: 200 | I39: =+H39 -> 200 | AB39: =SUM(I39:AA39) -> 200 | AC39: =+AB39-H39 -> 0
... A43: 2025-08-05 | B43: МӨНХЖАРГАЛ УГТАХБАЯР | C43: Charges for PORD Customer Payment :000450835280 | H43: 200 | I43: =+H43 -> 200 | AB43: =SUM(I43:AA43) -> 200 | AC43: =+AB43-H43 -> 0
...

Sheet 9
G1: 4145
D2: 252,525.9₮ | E2: 6,298,470.23₮ | F2: 6,045,944.33₮
A3: Сар | B3: Харилцагчийн нэр | C3: Харилцагчийн ТТД | D3: НӨАТ | E3: Цэвэр дүн | F3: Нийт дүн | G3: Татварын төрөл | H3: Нийт Зардал | I3: Оффис хангамж | J3: Зээл | K3: Хүнс / кэмп | L3: ХАБ | M3: Хангамж | N3: Засварт | O3: Сэлбэг | P3: Түлш | Q3: Тос тосолгоо | R3: Цалин | S3: НӨӨЦ ашигласны төлбөр | T3: торгууль | U3: Лиценз | V3: Нийгмийн Хариуцлага | W3: Нөхөн сэргэлтийн төлбөр | X3: хогны төлбөр | Y3: газрын төлбөр | Z3: Суутган | AA3: НДШ | AB3: нийт зардал | AC3: Зардлын зөрүү
D4: =SUM(D6:D162) -> 252525.9 | E4: =SUM(E6:E162) -> 6302615.2 | F4: =SUM(F6:F162) -> 6050089.3 | H4: =+AB4 -> 6302615.2 | I4: =SUM(I6:I162) -> 2774173 | J4: =SUM(J6:J162) -> 1762775.2 | K4: =SUM(K6:K162) -> 149600 | L4: =SUM(L6:L162) -> 0 | M4: =SUM(M6:M162) -> 37000 | N4: =SUM(N6:N162) -> 310000 | O4: =SUM(O6:O162) -> 822500 | P4: =SUM(P6:P162) -> 218067 | ... AA4: =SUM(AA6:AA162) -> 0 | AB4: =SUM(I4:AA4) -> 6302615.2 | AC4: =SUM(AC6:AC162) -> 0
F5: 1 | I5: =+I4/$H$4 -> 0.4401622 | K5: =+K4/$H$4 -> 0.023736178 | L5: =+L4/$H$4 -> 0 | M5: =+M4/$H$4 -> 0.0058705789 | N5: =+N4/$H$4 -> 0.049185931 | O5: =+O4/$H$4 -> 0.13050138 | P5: =+P4/$H$4 -> 0.034599447 | Q5: =+Q4/$H$4 -> 0.036254791 | R5: =+R4/$H$4 -> 0 | ... AC5: =+AC4/$H$4 -> 0
A6: 2025-09-10 | B6: ДОЛГОР БОЛДХУЯГ | C6: РД77112800 | D6: 0 | E6: 1880000 | F6: =+E6-D6 -> 1880000 | G6: Энгийн | H6: =+E6 -> 1880000 | I6: =+H6 -> 1880000 | AB6: =SUM(I6:AA6) -> 1880000 | AC6: =+AB6-H6 -> 0
A7: 2025-09-10 | B7: Их төмөрт | C7: 6036031 | D7: 28181.818 | E7: 310000 | F7: =+E7-D7 -> 281818.18 | G7: Энгийн | H7: =+E7 -> 310000 | N7: =+H7 -> 310000 | AB7: =SUM(I7:AA7) -> 310000 | AC7: =+AB7-H7 -> 0
A8: 2025-09-09 | B8: Нарлаг толгод | C8: 8420963 | D8: 8427.27 | E8: 92700 | F8: =+E8-D8 -> 84272.73 | G8: Энгийн | H8: =+E8 -> 92700 | I8: =+H8 -> 92700 | AB8: =SUM(I8:AA8) -> 92700 | AC8: =+AB8-H8 -> 0
A9: 2025-09-09 | B9: Хаянхярваа ОЮУНТУЯА | C9: УЮ87072401 | D9: 20772.73 | E9: 228500 | F9: =+E9-D9 -> 207727.27 | G9: Энгийн | H9: =+E9 -> 228500 | Q9: =+H9 -> 228500 | AB9: =SUM(I9:AA9) -> 228500 | AC9: =+AB9-H9 -> 0
A10: 2025-09-09 | B10: Нарлаг толгод | C10: 8420963 | D10: 3840 | E10: 42240 | F10: =+E10-D10 -> 38400 | G10: Энгийн | H10: =+E10 -> 42240 | I10: =+H10 -> 42240 | AB10: =SUM(I10:AA10) -> 42240 | AC10: =+AB10-H10 -> 0
A11: 2025-09-08 | B11: Энх арвай | C11: 6237614 | D11: 13600 | E11: 149600 | F11: =+E11-D11 -> 136000 | G11: Энгийн | H11: =+E11 -> 149600 | K11: =+H11 -> 149600 | AB11: =SUM(I11:AA11) -> 149600 | AC11: =+AB11-H11 -> 0
A12: 2025-09-07 | B12: НЯМЖАВ ОТГОНБААТАР | C12: УХ88122116 | D12: 0 | E12: 37000 | F12: =+E12-D12 -> 37000 | G12: Энгийн | H12: =+E12 -> 37000 | M12: =+H12 -> 37000 | AB12: =SUM(I12:AA12) -> 37000 | AC12: =+AB12-H12 -> 0
